Workbook
Name B: 'Tke lop mon'!$A$4:$N$13
Name B: #REF!

Sheet FPOLY_VIE1016
A1: Student ID | B1: Email | C1: Username | D1: Grade | E1: Quiz 1: Quiz 1 - SU21 | F1: Quiz 2: Quiz 2 - SU21 | G1: Quiz 3: Quiz 3 - SU21 | H1: Quiz 4: Quiz 4 - SU21 | I1: Quiz 5: Quiz 5 - SU21 | J1: Quiz 6: Quiz 6 - SU21 | K1: Quiz 7: Quiz 7 - SU21 | L1: Quiz 8: Quiz 8 - SU21 | M1: Quiz 9: Quiz 9 - SU21 | N1: Quiz 10: Quiz 10 - SU21 | O1: Quiz 11: Quiz 11 - SU21 | P1: Quiz 12: Quiz 12 - SU21 | Q1: Quiz 13: Quiz 13 - SU21 | R1: Quiz 14: Quiz 14 - SU21 | S1: Quiz (Avg) | T1: Assignment | U1: Final Test | V1: Enrollment Track | W1: Verification Status | X1: Certificate Eligible | Y1: Certificate Delivered | Z1: Certificate Type | AA1: Enrollment Status | AB1: å Quiz | AC1: å Quiz (Chưa học) | AD1: å Quiz (Đang học) | AE1: å Quiz (Đã đạt) | AF1: Tổng số Sv chưa tham gia học | AG1: Pass Quiz | AH1: ASM đạt | AI1: Điều kiện dự thi | AJ1: Lớp
A2: hanth17 | B2: hanth17@fpt.edu.vn | C2: hanth17 | D2: 0 | E2: Not Attempted | F2: Not Attempted | G2: Not Attempted | H2: Not Attempted | I2: Not Attempted | J2: Not Attempted | K2: Not Attempted | L2: Not Attempted | M2: Not Attempted | N2: Not Attempted | O2: Not Attempted | P2: Not Attempted | Q2: Not Attempted | R2: Not Attempted | S2: 0 | T2: Not Attempted | U2: Not Attempted | V2: audit | W2: N/A | X2: N | Y2: N | Z2: N/A | AA2: enrolled | AB2: 14 | AC2: =COUNTIF(E2:R2,"Not Attempted") -> 14 | AD2: =AB2-AC2-AE2 -> 0 | AE2: =COUNTIF(E2:R2,1) -> 0 | AF2: =IF(AC2=14,"Chưa tham gia học lần nào","") -> Chưa tham gia học lần nào | AG2: =IF(AND(MIN(E2:R2)>=1,COUNT(E2:R2)=COUNTA(E2:R2)),"Pass","Fail") -> Fail | AH2: =COUNT(T2,">=0.5") -> 0 | AI2: =IF(AND(AG2="Pass",AH2>=0.5),"Đủ Điều kiện dự thi","Fail") -> Fail | AJ2: =VLOOKUP(A2,'DSSV VIE1016'!$B$2:$D$55,3,0) -> #N/A
A3: dungptm | B3: DungPTM@fpt.edu.vn | C3: dungptm | D3: 0 | E3: Not Attempted | F3: Not Attempted | G3: Not Attempted | H3: Not Attempted | I3: Not Attempted | J3: Not Attempted | K3: Not Attempted | L3: Not Attempted | M3: Not Attempted | N3: Not Attempted | O3: Not Attempted | P3: Not Attempted | Q3: Not Attempted | R3: Not Attempted | S3: 0 | T3: Not Attempted | U3: Not Attempted | V3: audit | W3: N/A | X3: N | Y3: N | Z3: N/A | AA3: enrolled | AB3: 14 | AC3: =COUNTIF(E3:R3,"Not Attempted") -> 14 | AD3: =AB3-AC3-AE3 -> 0 | AE3: =COUNTIF(E3:R3,1) -> 0 | AF3: =IF(AC3=14,"Chưa tham gia học lần nào","") -> Chưa tham gia học lần nào | AG3: =IF(AND(MIN(E3:R3)>=1,COUNT(E3:R3)=COUNTA(E3:R3)),"Pass","Fail") -> Fail | AH3: =COUNT(T3,">=0.5") -> 0 | AI3: =IF(AND(AG3="Pass",AH3>=0.5),"Đủ Điều kiện dự thi","Fail") -> Fail | AJ3: =VLOOKUP(A3,'DSSV VIE1016'!$B$2:$D$55,3,0) -> #N/A
A4: pc02743 | B4: anhthpc02743@fpt.edu.vn | C4: anhthpc02743 | D4: 3 | E4: 1 | F4: 1 | G4: 1 | H4: 1 | I4: 1 | J4: 1 | K4: 1 | L4: 1 | M4: 1 | N4: 1 | O4: 1 | P4: 1 | Q4: 1 | R4: 1 | S4: 1 | T4: 1 | U4: 1 | V4: audit | W4: N/A | X4: N | Y4: N | Z4: N/A | AA4: enrolled | AB4: 14 | AC4: =COUNTIF(E4:R4,"Not Attempted") -> 0 | AD4: =AB4-AC4-AE4 -> 0 | AE4: =COUNTIF(E4:R4,1) -> 14 | AF4: =IF(AC4=14,"Chưa tham gia học lần nào","") | AG4: =IF(AND(MIN(E4:R4)>=1,COUNT(E4:R4)=COUNTA(E4:R4)),"Pass","Fail") -> Pass | AH4: =COUNT(T4,">=0.5") -> 1 | AI4: =IF(AND(AG4="Pass",AH4>=0.5),"Đủ Điều kiện dự thi","Fail") -> Đủ Điều kiện dự thi | AJ4: =VLOOKUP(A4,'DSSV VIE1016'!$B$2:$D$55,3,0) -> #N/A
A5: ph17782 | B5: quynhdtdph17782@fpt.edu.vn | C5: quynhdtdph17782 | D5: 3 | E5: 1 | F5: 1 | G5: 1 | H5: 1 | I5: 1 | J5: 1 | K5: 1 | L5: 1 | M5: 1 | N5: 1 | O5: 1 | P5: 1 | Q5: 1 | R5: 1 | S5: 1 | T5: 1 | U5: 1 | V5: audit | W5: N/A | X5: N | Y5: N | Z5: N/A | AA5: enrolled | AB5: 14 | AC5: =COUNTIF(E5:R5,"Not Attempted") -> 0 | AD5: =AB5-AC5-AE5 -> 0 | AE5: =COUNTIF(E5:R5,1) -> 14 | AF5: =IF(AC5=14,"Chưa tham gia học lần nào","") | AG5: =IF(AND(MIN(E5:R5)>=1,COUNT(E5:R5)=COUNTA(E5:R5)),"Pass","Fail") -> Pass | AH5: =COUNT(T5,">=0.5") -> 1 | AI5: =IF(AND(AG5="Pass",AH5>=0.5),"Đủ Điều kiện dự thi","Fail") -> Đủ Điều kiện dự thi | AJ5: =VLOOKUP(A5,'DSSV VIE1016'!$B$2:$D$55,3,0) -> #N/A
A6: ph13993 | B6: dainnph13993@fpt.edu.vn | C6: dainnph13993 | D6: 0 | E6: Not Attempted | F6: Not Attempted | G6: Not Attempted | H6: Not Attempted | I6: Not Attempted | J6: Not Attempted | K6: Not Attempted | L6: Not Attempted | M6: Not Attempted | N6: Not Attempted | O6: Not Attempted | P6: Not Attempted | Q6: Not Attempted | R6: Not Attempted | S6: 0 | T6: Not Attempted | U6: Not Attempted | V6: audit | W6: N/A | X6: N | Y6: N | Z6: N/A | AA6: enrolled | AB6: 14 | AC6: =COUNTIF(E6:R6,"Not Attempted") -> 14 | AD6: =AB6-AC6-AE6 -> 0 | AE6: =COUNTIF(E6:R6,1) -> 0 | AF6: =IF(AC6=14,"Chưa tham gia học lần nào","") -> Chưa tham gia học lần nào | AG6: =IF(AND(MIN(E6:R6)>=1,COUNT(E6:R6)=COUNTA(E6:R6)),"Pass","Fail") -> Fail | AH6: =COUNT(T6,">=0.5") -> 0 | AI6: =IF(AND(AG6="Pass",AH6>=0.5),"Đủ Điều kiện dự thi","Fail") -> Fail | AJ6: =VLOOKUP(A6,'DSSV VIE1016'!$B$2:$D$55,3,0) -> #N/A
A7: ph16793 | B7: kimdtph16793@fpt.edu.vn | C7: kimdtph16793 | D7: 3 | E7: 1 | F7: 1 | G7: 1 | H7: 1 | I7: 1 | J7: 1 | K7: 1 | L7: 1 | M7: 1 | N7: 1 | O7: 1 | P7: 1 | Q7: 1 | R7: 1 | S7: 1 | T7: 1 | U7: 1 | V7: audit | W7: N/A | X7: N | Y7: N | Z7: N/A | AA7: enrolled | AB7: 14 | AC7: =COUNTIF(E7:R7,"Not Attempted") -> 0 | AD7: =AB7-AC7-AE7 -> 0 | AE7: =COUNTIF(E7:R7,1) -> 14 | AF7: =IF(AC7=14,"Chưa tham gia học lần nào","") | AG7: =IF(AND(MIN(E7:R7)>=1,COUNT(E7:R7)=COUNTA(E7:R7)),"Pass","Fail") -> Pass | AH7: =COUNT(T7,">=0.5") -> 1 | AI7: =IF(AND(AG7="Pass",AH7>=0.5),"Đủ Điều kiện dự thi","Fail") -> Đủ Điều kiện dự thi | AJ7: =VLOOKUP(A7,'DSSV VIE1016'!$B$2:$D$55,3,0) -> #N/A
A8: ps13915 | B8: hiendtmps13915@fpt.edu.vn | C8: hiendtmps13915 | D8: 0 | E8: Not Attempted | F8: Not Attempted | G8: Not Attempted | H8: Not Attempted | I8: Not Attempted | J8: Not Attempted | K8: Not Attempted | L8: Not Attempted | M8: Not Attempted | N8: Not Attempted | O8: Not Attempted | P8: Not Attempted | Q8: Not Attempted | R8: Not Attempted | S8: 0 | T8: Not Attempted | U8: Not Attempted | V8: audit | W8: N/A | X8: N | Y8: N | Z8: N/A | AA8: enrolled | AB8: 14 | AC8: =COUNTIF(E8:R8,"Not Attempted") -> 14 | AD8: =AB8-AC8-AE8 -> 0 | AE8: =COUNTIF(E8:R8,1) -> 0 | AF8: =IF(AC8=14,"Chưa tham gia học lần nào","") -> Chưa tham gia học lần nào | AG8: =IF(AND(MIN(E8:R8)>=1,COUNT(E8:R8)=COUNTA(E8:R8)),"Pass","Fail") -> Fail | AH8: =COUNT(T8,">=0.5") -> 0 | AI8: =IF(AND(AG8="Pass",AH8>=0.5),"Đủ Điều kiện dự thi","Fail") -> Fail | AJ8: =VLOOKUP(A8,'DSSV VIE1016'!$B$2:$D$55,3,0) -> #N/A
A9: ph12530 | B9: haidmph12530@fpt.edu.vn | C9: haidmph12530 | D9: 0 | E9: Not Attempted | F9: Not Attempted | G9: Not Attempted | H9: Not Attempted | I9: Not Attempted | J9: Not Attempted | K9: Not Attempted | L9: Not Attempted | M9: Not Attempted | N9: Not Attempted | O9: Not Attempted | P9: Not Attempted | Q9: Not Attempted | R9: Not Attempted | S9: 0 | T9: Not Attempted | U9: Not Attempted | V9: audit | W9: N/A | X9: N | Y9: N | Z9: N/A | AA9: enrolled | AB9: 14 | AC9: =COUNTIF(E9:R9,"Not Attempted") -> 14 | AD9: =AB9-AC9-AE9 -> 0 | AE9: =COUNTIF(E9:R9,1) -> 0 | AF9: =IF(AC9=14,"Chưa tham gia học lần nào","") -> Chưa tham gia học lần nào | AG9: =IF(AND(MIN(E9:R9)>=1,COUNT(E9:R9)=COUNTA(E9:R9)),"Pass","Fail") -> Fail | AH9: =COUNT(T9,">=0.5") -> 0 | AI9: =IF(AND(AG9="Pass",AH9>=0.5),"Đủ Điều kiện dự thi","Fail") -> Fail | AJ9: =VLOOKUP(A9,'DSSV VIE1016'!$B$2:$D$55,3,0) -> #N/A
A10: pg00556 | B10: thaodttpg00556@fpt.edu.vn | C10: thaodttpg00556 | D10: 0 | E10: Not Attempted | F10: Not Attempted | G10: Not Attempted | H10: Not Attempted | I10: Not Attempted | J10: Not Attempted | K10: Not Attempted | L10: Not Attempted | M10: Not Attempted | N10: Not Attempted | O10: Not Attempted | P10: Not Attempted | Q10: Not Attempted | R10: Not Attempted | S10: 0 | T10: Not Attempted | U10: Not Attempted | V10: audit | W10: N/A | X10: N | Y10: N | Z10: N/A | AA10: enrolled | AB10: 14 | AC10: =COUNTIF(E10:R10,"Not Attempted") -> 14 | AD10: =AB10-AC10-AE10 -> 0 | AE10: =COUNTIF(E10:R10,1) -> 0 | AF10: =IF(AC10=14,"Chưa tham gia học lần nào","") -> Chưa tham gia học lần nào | AG10: =IF(AND(MIN(E10:R10)>=1,COUNT(E10:R10)=COUNTA(E10:R10)),"Pass","Fail") -> Fail | AH10: =COUNT(T10,">=0.5") -> 0 | AI10: =IF(AND(AG10="Pass",AH10>=0.5),"Đủ Điều kiện dự thi","Fail") -> Fail | AJ10: =VLOOKUP(A10,'DSSV VIE1016'!$B$2:$D$55,3,0) -> #N/A
A11: ph16985 | B11: baudmph16985@fpt.edu.vn | C11: baudmph16985 | D11: 3 | E11: 1 | F11: 1 | G11: 1 | H11: 1 | I11: 1 | J11: 1 | K11: 1 | L11: 1 | M11: 1 | N11: 1 | O11: 1 | P11: 1 | Q11: 1 | R11: 1 | S11: 1 | T11: 1 | U11: 1 | V11: audit | W11: N/A | X11: N | Y11: N | Z11: N/A | AA11: enrolled | AB11: 14 | AC11: =COUNTIF(E11:R11,"Not Attempted") -> 0 | AD11: =AB11-AC11-AE11 -> 0 | AE11: =COUNTIF(E11:R11,1) -> 14 | AF11: =IF(AC11=14,"Chưa tham gia học lần nào","") | AG11: =IF(AND(MIN(E11:R11)>=1,COUNT(E11:R11)=COUNTA(E11:R11)),"Pass","Fail") -> Pass | AH11: =COUNT(T11,">=0.5") -> 1 | AI11: =IF(AND(AG11="Pass",AH11>=0.5),"Đủ Điều kiện dự thi","Fail") -> Đủ Điều kiện dự thi | AJ11: =VLOOKUP(A11,'DSSV VIE1016'!$B$2:$D$55,3,0) -> #N/A
A12: ph12649 | B12: vanntph12649@fpt.edu.vn | C12: vanntph12649 | D12: 0 | E12: Not Attempted | F12: Not Attempted | G12: Not Attempted | H12: Not Attempted | I12: Not Attempted | J12: Not Attempted | K12: Not Attempted | L12: Not Attempted | M12: Not Attempted | N12: Not Attempted | O12: Not Attempted | P12: Not Attempted | Q12: Not Attempted | R12: Not Attempted | S12: 0 | T12: Not Attempted | U12: Not Attempted | V12: audit | W12: N/A | X12: N | Y12: N | Z12: N/A | AA12: enrolled | AB12: 14 | AC12: =COUNTIF(E12:R12,"Not Attempted") -> 14 | AD12: =AB12-AC12-AE12 -> 0 | AE12: =COUNTIF(E12:R12,1) -> 0 | AF12: =IF(AC12=14,"Chưa tham gia học lần nào","") -> Chưa tham gia học lần nào | AG12: =IF(AND(MIN(E12:R12)>=1,COUNT(E12:R12)=COUNTA(E12:R12)),"Pass","Fail") -> Fail | AH12: =COUNT(T12,">=0.5") -> 0 | AI12: =IF(AND(AG12="Pass",AH12>=0.5),"Đủ Điều kiện dự thi","Fail") -> Fail | AJ12: =VLOOKUP(A12,'DSSV VIE1016'!$B$2:$D$55,3,0) -> #N/A
A13: ph11496 | B13: tunglvph11496@fpt.edu.vn | C13: tunglvph11496 | D13: 2 | E13: 1 | F13: 1 | G13: 1 | H13: 1 | I13: 1 | J13: 1 | K13: 1 | L13: 1 | M13: 1 | N13: 1 | O13: 1 | P13: 1 | Q13: 1 | R13: 1 | S13: 1 | T13: 1 | U13: Not Attempted | V13: audit | W13: N/A | X13: N | Y13: N | Z13: N/A | AA13: enrolled | AB13: 14 | AC13: =COUNTIF(E13:R13,"Not Attempted") -> 0 | AD13: =AB13-AC13-AE13 -> 0 | AE13: =COUNTIF(E13:R13,1) -> 14 | AF13: =IF(AC13=14,"Chưa tham gia học lần nào","") | AG13: =IF(AND(MIN(E13:R13)>=1,COUNT(E13:R13)=COUNTA(E13:R13)),"Pass","Fail") -> Pass | AH13: =COUNT(T13,">=0.5") -> 1 | AI13: =IF(AND(AG13="Pass",AH13>=0.5),"Đủ Điều kiện dự thi","Fail") -> Đủ Điều kiện dự thi | AJ13: =VLOOKUP(A13,'DSSV VIE1016'!$B$2:$D$55,3,0) -> #N/A
A14: pd03691 | B14: hieplbpd03691@fpt.edu.vn | C14: hieplbpd03691 | D14: 3 | E14: 1 | F14: 1 | G14: 1 | H14: 1 | I14: 1 | J14: 1 | K14: 1 | L14: 1 | M14: 1 | N14: 1 | O14: 1 | P14: 1 | Q14: 1 | R14: 1 | S14: 1 | T14: 1 | U14: 1 | V14: audit | W14: N/A | X14: N | Y14: N | Z14: N/A | AA14: enrolled | AB14: 14 | AC14: =COUNTIF(E14:R14,"Not Attempted") -> 0 | AD14: =AB14-AC14-AE14 -> 0 | AE14: =COUNTIF(E14:R14,1) -> 14 | AF14: =IF(AC14=14,"Chưa tham gia học lần nào","") | AG14: =IF(AND(MIN(E14:R14)>=1,COUNT(E14:R14)=COUNTA(E14:R14)),"Pass","Fail") -> Pass | AH14: =COUNT(T14,">=0.5") -> 1 | AI14: =IF(AND(AG14="Pass",AH14>=0.5),"Đủ Điều kiện dự thi","Fail") -> Đủ Điều kiện dự thi | AJ14: =VLOOKUP(A14,'DSSV VIE1016'!$B$2:$D$55,3,0) -> #N/A
A15: ph12204 | B15: hiepdtnph12204@fpt.edu.vn | C15: hiepdtnph12204 | D15: 2 | E15: 1 | F15: 1 | G15: 1 | H15: 1 | I15: 1 | J15: 1 | K15: 1 | L15: 1 | M15: 1 | N15: 1 | O15: 1 | P15: 1 | Q15: 1 | R15: 1 | S15: 1 | T15: 1 | U15: Not Attempted | V15: audit | W15: N/A | X15: N | Y15: N | Z15: N/A | AA15: enrolled | AB15: 14 | AC15: =COUNTIF(E15:R15,"Not Attempted") -> 0 | AD15: =AB15-AC15-AE15 -> 0 | AE15: =COUNTIF(E15:R15,1) -> 14 | AF15: =IF(AC15=14,"Chưa tham gia học lần nào","") | AG15: =IF(AND(MIN(E15:R15)>=1,COUNT(E15:R15)=COUNTA(E15:R15)),"Pass","Fail") -> Pass | AH15: =COUNT(T15,">=0.5") -> 1 | AI15: =IF(AND(AG15="Pass",AH15>=0.5),"Đủ Điều kiện dự thi","Fail") -> Đủ Điều kiện dự thi | AJ15: =VLOOKUP(A15,'DSSV VIE1016'!$B$2:$D$55,3,0) -> #N/A
A16: pc01645 | B16: nganttpc01645@fpt.edu.vn | C16: nganttpc01645 | D16: 3 | E16: 1 | F16: 1 | G16: 1 | H16: 1 | I16: 1 | J16: 1 | K16: 1 | L16: 1 | M16: 1 | N16: 1 | O16: 1 | P16: 1 | Q16: 1 | R16: 1 | S16: 1 | T16: 1 | U16: 1 | V16: audit | W16: N/A | X16: N | Y16: N | Z16: N/A | AA16: enrolled | AB16: 14 | AC16: =COUNTIF(E16:R16,"Not Attempted") -> 0 | AD16: =AB16-AC16-AE16 -> 0 | AE16: =COUNTIF(E16:R16,1) -> 14 | AF16: =IF(AC16=14,"Chưa tham gia học lần nào","") | AG16: =IF(AND(MIN(E16:R16)>=1,COUNT(E16:R16)=COUNTA(E16:R16)),"Pass","Fail") -> Pass | AH16: =COUNT(T16,">=0.5") -> 1 | AI16: =IF(AND(AG16="Pass",AH16>=0.5),"Đủ Điều kiện dự thi","Fail") -> Đủ Điều kiện dự thi | AJ16: =VLOOKUP(A16,'DSSV VIE1016'!$B$2:$D$55,3,0) -> #N/A
A17: pc02333 | B17: khiemthpc02333@fpt.edu.vn | C17: khiemthpc02333 | D17: 0.07 | E17: 1 | F17: Not Attempted | G17: Not Attempted | H17: Not Attempted | I17: Not Attempted | J17: Not Attempted | K17: Not Attempted | L17: Not Attempted | M17: Not Attempted | N17: Not Attempted | O17: Not Attempted | P17: Not Attempted | Q17: Not Attempted | R17: Not Attempted | S17: 0.071428571 | T17: Not Attempted | U17: Not Attempted | V17: audit | W17: N/A | X17: N | Y17: N | Z17: N/A | AA17: enrolled | AB17: 14 | AC17: =COUNTIF(E17:R17,"Not Attempted") -> 13 | AD17: =AB17-AC17-AE17 -> 0 | AE17: =COUNTIF(E17:R17,1) -> 1 | AF17: =IF(AC17=14,"Chưa tham gia học lần nào","") | AG17: =IF(AND(MIN(E17:R17)>=1,COUNT(E17:R17)=COUNTA(E17:R17)),"Pass","Fail") -> Fail | AH17: =COUNT(T17,">=0.5") -> 0 | AI17: =IF(AND(AG17="Pass",AH17>=0.5),"Đủ Điều kiện dự thi","Fail") -> Fail | AJ17: =VLOOKUP(A17,'DSSV VIE1016'!$B$2:$D$55,3,0) -> #N/A
A18: pc01553 | B18: nhanntpc01553@fpt.edu.vn | C18: nhanntpc01553 | D18: 1.9 | E18: 1 | F18: 1 | G18: 1 | H18: 1 | I18: 1 | J18: 1 | K18: 1 | L18: 1 | M18: 1 | N18: 1 | O18: 1 | P18: 1 | Q18: 1 | R18: 1 | S18: 1 | T18: 0.9 | U18: Not Attempted | V18: audit | W18: N/A | X18: N | Y18: N | Z18: N/A | AA18: enrolled | AB18: 14 | AC18: =COUNTIF(E18:R18,"Not Attempted") -> 0 | AD18: =AB18-AC18-AE18 -> 0 | AE18: =COUNTIF(E18:R18,1) -> 14 | AF18: =IF(AC18=14,"Chưa tham gia học lần nào","") | AG18: =IF(AND(MIN(E18:R18)>=1,COUNT(E18:R18)=COUNTA(E18:R18)),"Pass","Fail") -> Pass | AH18: =COUNT(T18,">=0.5") -> 1 | AI18: =IF(AND(AG18="Pass",AH18>=0.5),"Đủ Điều kiện dự thi","Fail") -> Đủ Điều kiện dự thi | AJ18: =VLOOKUP(A18,'DSSV VIE1016'!$B$2:$D$55,3,0) -> #N/A
A19: ph17948 | B19: anhntqph17948@fpt.edu.vn | C19: anhntqph17948 | D19: 3 | E19: 1 | F19: 1 | G19: 1 | H19: 1 | I19: 1 | J19: 1 | K19: 1 | L19: 1 | M19: 1 | N19: 1 | O19: 1 | P19: 1 | Q19: 1 | R19: 1 | S19: 1 | T19: 1 | U19: 1 | V19: audit | W19: N/A | X19: N | Y19: N | Z19: N/A | AA19: enrolled | AB19: 14 | AC19: =COUNTIF(E19:R19,"Not Attempted") -> 0 | AD19: =AB19-AC19-AE19 -> 0 | AE19: =COUNTIF(E19:R19,1) -> 14 | AF19: =IF(AC19=14,"Chưa tham gia học lần nào","") | AG19: =IF(AND(MIN(E19:R19)>=1,COUNT(E19:R19)=COUNTA(E19:R19)),"Pass","Fail") -> Pass | AH19: =COUNT(T19,">=0.5") -> 1 | AI19: =IF(AND(AG19="Pass",AH19>=0.5),"Đủ Điều kiện dự thi","Fail") -> Đủ Điều kiện dự thi | AJ19: =VLOOKUP(A19,'DSSV VIE1016'!$B$2:$D$55,3,0) -> #N/A
A20: pc02712 | B20: huongkthpc02712@fpt.edu.vn | C20: huongkthpc02712 | D20: 2 | E20: 1 | F20: 1 | G20: 1 | H20: 1 | I20: 1 | J20: 1 | K20: 1 | L20: 1 | M20: 1 | N20: 1 | O20: 1 | P20: 1 | Q20: 1 | R20: 1 | S20: 1 | T20: Not Attempted | U20: 1 | V20: audit | W20: N/A | X20: N | Y20: N | Z20: N/A | AA20: enrolled | AB20: 14 | AC20: =COUNTIF(E20:R20,"Not Attempted") -> 0 | AD20: =AB20-AC20-AE20 -> 0 | AE20: =COUNTIF(E20:R20,1) -> 14 | AF20: =IF(AC20=14,"Chưa tham gia học lần nào","") | AG20: =IF(AND(MIN(E20:R20)>=1,COUNT(E20:R20)=COUNTA(E20:R20)),"Pass","Fail") -> Pass | AH20: =COUNT(T20,">=0.5") -> 0 | AI20: =IF(AND(AG20="Pass",AH20>=0.5),"Đủ Điều kiện dự thi","Fail") -> Fail | AJ20: =VLOOKUP(A20,'DSSV VIE1016'!$B$2:$D$55,3,0) -> #N/A
A21: ph17998 | B21: ngocttbph17998@fpt.edu.vn | C21: ngocttbph17998 | D21: 3 | E21: 1 | F21: 1 | G21: 1 | H21: 1 | I21: 1 | J21: 1 | K21: 1 | L21: 1 | M21: 1 | N21: 1 | O21: 1 | P21: 1 | Q21: 1 | R21: 1 | S21: 1 | T21: 1 | U21: 1 | V21: audit | W21: N/A | X21: N | Y21: N | Z21: N/A | AA21: enrolled | AB21: 14 | AC21: =COUNTIF(E21:R21,"Not Attempted") -> 0 | AD21: =AB21-AC21-AE21 -> 0 | AE21: =COUNTIF(E21:R21,1) -> 14 | AF21: =IF(AC21=14,"Chưa tham gia học lần nào","") | AG21: =IF(AND(MIN(E21:R21)>=1,COUNT(E21:R21)=COUNTA(E21:R21)),"Pass","Fail") -> Pass | AH21: =COUNT(T21,">=0.5") -> 1 | AI21: =IF(AND(AG21="Pass",AH21>=0.5),"Đủ Điều kiện dự thi","Fail") -> Đủ Điều kiện dự thi | AJ21: =VLOOKUP(A21,'DSSV VIE1016'!$B$2:$D$55,3,0) -> #N/A
A22: pc01548 | B22: datntpc01548@fpt.edu.vn | C22: datntpc01548 | D22: 3 | E22: 1 | F22: 1 | G22: 1 | H22: 1 | I22: 1 | J22: 1 | K22: 1 | L22: 1 | M22: 1 | N22: 1 | O22: 1 | P22: 1 | Q22: 1 | R22: 1 | S22: 1 | T22: 1 | U22: 1 | V22: audit | W22: N/A | X22: N | Y22: N | Z22: N/A | AA22: enrolled | AB22: 14 | AC22: =COUNTIF(E22:R22,"Not Attempted") -> 0 | AD22: =AB22-AC22-AE22 -> 0 | AE22: =COUNTIF(E22:R22,1) -> 14 | AF22: =IF(AC22=14,"Chưa tham gia học lần nào","") | AG22: =IF(AND(MIN(E22:R22)>=1,COUNT(E22:R22)=COUNTA(E22:R22)),"Pass","Fail") -> Pass | AH22: =COUNT(T22,">=0.5") -> 1 | AI22: =IF(AND(AG22="Pass",AH22>=0.5),"Đủ Điều kiện dự thi","Fail") -> Đủ Điều kiện dự thi | AJ22: =VLOOKUP(A22,'DSSV VIE1016'!$B$2:$D$55,3,0) -> #N/A
A23: anhvv | B23: anhvv@fpt.edu.vn | C23: anhvv | D23: 0 | E23: Not Attempted | F23: Not Attempted | G23: Not Attempted | H23: Not Attempted | I23: Not Attempted | J23: Not Attempted | K23: Not Attempted | L23: Not Attempted | M23: Not Attempted | N23: Not Attempted | O23: Not Attempted | P23: Not Attempted | Q23: Not Attempted | R23: Not Attempted | S23: 0 | T23: Not Attempted | U23: Not Attempted | V23: audit | W23: N/A | X23: N | Y23: N | Z23: N/A | AA23: enrolled | AB23: 14 | AC23: =COUNTIF(E23:R23,"Not Attempted") -> 14 | AD23: =AB23-AC23-AE23 -> 0 | AE23: =COUNTIF(E23:R23,1) -> 0 | AF23: =IF(AC23=14,"Chưa tham gia học lần nào","") -> Chưa tham gia học lần nào | AG23: =IF(AND(MIN(E23:R23)>=1,COUNT(E23:R23)=COUNTA(E23:R23)),"Pass","Fail") -> Fail | AH23: =COUNT(T23,">=0.5") -> 0 | AI23: =IF(AND(AG23="Pass",AH23>=0.5),"Đủ Điều kiện dự thi","Fail") -> Fail | AJ23: =VLOOKUP(A23,'DSSV VIE1016'!$B$2:$D$55,3,0) -> #N/A
A24: pc02374 | B24: duynhpc02374@fpt.edu.vn | C24: duynhpc02374 | D24: 3 | E24: 1 | F24: 1 | G24: 1 | H24: 1 | I24: 1 | J24: 1 | K24: 1 | L24: 1 | M24: 1 | N24: 1 | O24: 1 | P24: 1 | Q24: 1 | R24: 1 | S24: 1 | T24: 1 | U24: 1 | V24: audit | W24: N/A | X24: N | Y24: N | Z24: N/A | AA24: enrolled | AB24: 14 | AC24: =COUNTIF(E24:R24,"Not Attempted") -> 0 | AD24: =AB24-AC24-AE24 -> 0 | AE24: =COUNTIF(E24:R24,1) -> 14 | AF24: =IF(AC24=14,"Chưa tham gia học lần nào","") | AG24: =IF(AND(MIN(E24:R24)>=1,COUNT(E24:R24)=COUNTA(E24:R24)),"Pass","Fail") -> Pass | AH24: =COUNT(T24,">=0.5") -> 1 | AI24: =IF(AND(AG24="Pass",AH24>=0.5),"Đủ Điều kiện dự thi","Fail") -> Đủ Điều kiện dự thi | AJ24: =VLOOKUP(A24,'DSSV VIE1016'!$B$2:$D$55,3,0) -> #N/A
A25: ph14476 | B25: hueptmph14476@fpt.edu.vn | C25: hueptmph14476 | D25: 3 | E25: 1 | F25: 1 | G25: 1 | H25: 1 | I25: 1 | J25: 1 | K25: 1 | L25: 1 | M25: 1 | N25: 1 | O25: 1 | P25: 1 | Q25: 1 | R25: 1 | S25: 1 | T25: 1 | U25: 1 | V25: audit | W25: N/A | X25: N | Y25: N | Z25: N/A | AA25: enrolled | AB25: 14 | AC25: =COUNTIF(E25:R25,"Not Attempted") -> 0 | AD25: =AB25-AC25-AE25 -> 0 | AE25: =COUNTIF(E25:R25,1) -> 14 | AF25: =IF(AC25=14,"Chưa tham gia học lần nào","") | AG25: =IF(AND(MIN(E25:R25)>=1,COUNT(E25:R25)=COUNTA(E25:R25)),"Pass","Fail") -> Pass | AH25: =COUNT(T25,">=0.5") -> 1 | AI25: =IF(AND(AG25="Pass",AH25>=0.5),"Đủ Điều kiện dự thi","Fail") -> Đủ Điều kiện dự thi | AJ25: =VLOOKUP(A25,'DSSV VIE1016'!$B$2:$D$55,3,0) -> #N/A
A26: pc01485 | B26: taindpc01485@fpt.edu.vn | C26: taindpc01485 | D26: 3 | E26: 1 | F26: 1 | G26: 1 | H26: 1 | I26: 1 | J26: 1 | K26: 1 | L26: 1 | M26: 1 | N26: 1 | O26: 1 | P26: 1 | Q26: 1 | R26: 1 | S26: 1 | T26: 1 | U26: 1 | V26: audit | W26: N/A | X26: N | Y26: N | Z26: N/A | AA26: enrolled | AB26: 14 | AC26: =COUNTIF(E26:R26,"Not Attempted") -> 0 | AD26: =AB26-AC26-AE26 -> 0 | AE26: =COUNTIF(E26:R26,1) -> 14 | AF26: =IF(AC26=14,"Chưa tham gia học lần nào","") | AG26: =IF(AND(MIN(E26:R26)>=1,COUNT(E26:R26)=COUNTA(E26:R26)),"Pass","Fail") -> Pass | AH26: =COUNT(T26,">=0.5") -> 1 | AI26: =IF(AND(AG26="Pass",AH26>=0.5),"Đủ Điều kiện dự thi","Fail") -> Đủ Điều kiện dự thi | AJ26: =VLOOKUP(A26,'DSSV VIE1016'!$B$2:$D$55,3,0) -> #N/A
A27: pc02669 | B27: anhtdpc02669@fpt.edu.vn | C27: anhtdpc02669 | D27: 2 | E27: 1 | F27: 1 | G27: 1 | H27: 1 | I27: 1 | J27: 1 | K27: 1 | L27: 1 | M27: 1 | N27: 1 | O27: 1 | P27: 1 | Q27: 1 | R27: 1 | S27: 1 | T27: 1 | U27: Not Attempted | V27: audit | W27: N/A | X27: N | Y27: N | Z27: N/A | AA27: enrolled | AB27: 14 | AC27: =COUNTIF(E27:R27,"Not Attempted") -> 0 | AD27: =AB27-AC27-AE27 -> 0 | AE27: =COUNTIF(E27:R27,1) -> 14 | AF27: =IF(AC27=14,"Chưa tham gia học lần nào","") | AG27: =IF(AND(MIN(E27:R27)>=1,COUNT(E27:R27)=COUNTA(E27:R27)),"Pass","Fail") -> Pass | AH27: =COUNT(T27,">=0.5") -> 1 | AI27: =IF(AND(AG27="Pass",AH27>=0.5),"Đủ Điều kiện dự thi","Fail") -> Đủ Điều kiện dự thi | AJ27: =VLOOKUP(A27,'DSSV VIE1016'!$B$2:$D$55,3,0) -> #N/A
A28: ph17013 | B28: cuongptph17013@fpt.edu.vn | C28: cuongptph17013 | D28: 2 | E28: 1 | F28: 1 | G28: 1 | H28: 1 | I28: 1 | J28: 1 | K28: 1 | L28: 1 | M28: 1 | N28: 1 | O28: 1 | P28: 1 | Q28: 1 | R28: 1 | S28: 1 | T28: 1 | U28: Not Attempted | V28: audit | W28: N/A | X28: N | Y28: N | Z28: N/A | AA28: enrolled | AB28: 14 | AC28: =COUNTIF(E28:R28,"Not Attempted") -> 0 | AD28: =AB28-AC28-AE28 -> 0 | AE28: =COUNTIF(E28:R28,1) -> 14 | AF28: =IF(AC28=14,"Chưa tham gia học lần nào","") | AG28: =IF(AND(MIN(E28:R28)>=1,COUNT(E28:R28)=COUNTA(E28:R28)),"Pass","Fail") -> Pass | AH28: =COUNT(T28,">=0.5") -> 1 | AI28: =IF(AND(AG28="Pass",AH28>=0.5),"Đủ Điều kiện dự thi","Fail") -> Đủ Điều kiện dự thi | AJ28: =VLOOKUP(A28,'DSSV VIE1016'!$B$2:$D$55,3,0) -> #N/A
A29: pc01968 | B29: tranhthpc01968@fpt.edu.vn | C29: tranhthpc01968 | D29: 3 | E29: 1 | F29: 1 | G29: 1 | H29: 1 | I29: 1 | J29: 1 | K29: 1 | L29: 1 | M29: 1 | N29: 1 | O29: 1 | P29: 1 | Q29: 1 | R29: 1 | S29: 1 | T29: 1 | U29: 1 | V29: audit | W29: N/A | X29: N | Y29: N | Z29: N/A | AA29: enrolled | AB29: 14 | AC29: =COUNTIF(E29:R29,"Not Attempted") -> 0 | AD29: =AB29-AC29-AE29 -> 0 | AE29: =COUNTIF(E29:R29,1) -> 14 | AF29: =IF(AC29=14,"Chưa tham gia học lần nào","") | AG29: =IF(AND(MIN(E29:R29)>=1,COUNT(E29:R29)=COUNTA(E29:R29)),"Pass","Fail") -> Pass | AH29: =COUNT(T29,">=0.5") -> 1 | AI29: =IF(AND(AG29="Pass",AH29>=0.5),"Đủ Điều kiện dự thi","Fail") -> Đủ Điều kiện dự thi | AJ29: =VLOOKUP(A29,'DSSV VIE1016'!$B$2:$D$55,3,0) -> #N/A
A30: pc01480 | B30: vyhtpc01480@fpt.edu.vn | C30: vyhtpc01480 | D30: 3 | E30: 1 | F30: 1 | G30: 1 | H30: 1 | I30: 1 | J30: 1 | K30: 1 | L30: 1 | M30: 1 | N30: 1 | O30: 1 | P30: 1 | Q30: 1 | R30: 1 | S30: 1 | T30: 1 | U30: 1 | V30: audit | W30: N/A | X30: N | Y30: N | Z30: N/A | AA30: enrolled | AB30: 14 | AC30: =COUNTIF(E30:R30,"Not Attempted") -> 0 | AD30: =AB30-AC30-AE30 -> 0 | AE30: =COUNTIF(E30:R30,1) -> 14 | AF30: =IF(AC30=14,"Chưa tham gia học lần nào","") | AG30: =IF(AND(MIN(E30:R30)>=1,COUNT(E30:R30)=COUNTA(E30:R30)),"Pass","Fail") -> Pass | AH30: =COUNT(T30,">=0.5") -> 1 | AI30: =IF(AND(AG30="Pass",AH30>=0.5),"Đủ Điều kiện dự thi","Fail") -> Đủ Điều kiện dự thi | AJ30: =VLOOKUP(A30,'DSSV VIE1016'!$B$2:$D$55,3,0) -> #N/A
A31: ps06129 | B31: nguyenndps06129@fpt.edu.vn | C31: nguyenndps06129 | D31: 0 | E31: Not Attempted | F31: Not Attempted | G31: Not Attempted | H31: Not Attempted | I31: Not Attempted | J31: Not Attempted | K31: Not Attempted | L31: Not Attempted | M31: Not Attempted | N31: Not Attempted | O31: Not Attempted | P31: Not Attempted | Q31: Not Attempted | R31: Not Attempted | S31: 0 | T31: Not Attempted | U31: Not Attempted | V31: audit | W31: N/A | X31: N | Y31: N | Z31: N/A | AA31: enrolled | AB31: 14 | AC31: =COUNTIF(E31:R31,"Not Attempted") -> 14 | AD31: =AB31-AC31-AE31 -> 0 | AE31: =COUNTIF(E31:R31,1) -> 0 | AF31: =IF(AC31=14,"Chưa tham gia học lần nào","") -> Chưa tham gia học lần nào | AG31: =IF(AND(MIN(E31:R31)>=1,COUNT(E31:R31)=COUNTA(E31:R31)),"Pass","Fail") -> Fail | AH31: =COUNT(T31,">=0.5") -> 0 | AI31: =IF(AND(AG31="Pass",AH31>=0.5),"Đủ Điều kiện dự thi","Fail") -> Fail | AJ31: =VLOOKUP(A31,'DSSV VIE1016'!$B$2:$D$55,3,0) -> #N/A
A32: pc01555 | B32: trinhtndpc01555@fpt.edu.vn | C32: trinhtndpc01555 | D32: 2.9 | E32: 1 | F32: 1 | G32: 1 | H32: 1 | I32: 1 | J32: 1 | K32: 1 | L32: 1 | M32: 1 | N32: 1 | O32: 1 | P32: 1 | Q32: 1 | R32: 1 | S32: 1 | T32: 0.9 | U32: 1 | V32: audit | W32: N/A | X32: N | Y32: N | Z32: N/A | AA32: enrolled | AB32: 14 | AC32: =COUNTIF(E32:R32,"Not Attempted") -> 0 | AD32: =AB32-AC32-AE32 -> 0 | AE32: =COUNTIF(E32:R32,1) -> 14 | AF32: =IF(AC32=14,"Chưa tham gia học lần nào","") | AG32: =IF(AND(MIN(E32:R32)>=1,COUNT(E32:R32)=COUNTA(E32:R32)),"Pass","Fail") -> Pass | AH32: =COUNT(T32,">=0.5") -> 1 | AI32: =IF(AND(AG32="Pass",AH32>=0.5),"Đủ Điều kiện dự thi","Fail") -> Đủ Điều kiện dự thi | AJ32: =VLOOKUP(A32,'DSSV VIE1016'!$B$2:$D$55,3,0) -> #N/A
A33: ph14984 | B33: hungndph14984@fpt.edu.vn | C33: hungndph14984 | D33: 3 | E33: 1 | F33: 1 | G33: 1 | H33: 1 | I33: 1 | J33: 1 | K33: 1 | L33: 1 | M33: 1 | N33: 1 | O33: 1 | P33: 1 | Q33: 1 | R33: 1 | S33: 1 | T33: 1 | U33: 1 | V33: audit | W33: N/A | X33: N | Y33: N | Z33: N/A | AA33: enrolled | AB33: 14 | AC33: =COUNTIF(E33:R33,"Not Attempted") -> 0 | AD33: =AB33-AC33-AE33 -> 0 | AE33: =COUNTIF(E33:R33,1) -> 14 | AF33: =IF(AC33=14,"Chưa tham gia học lần nào","") | AG33: =IF(AND(MIN(E33:R33)>=1,COUNT(E33:R33)=COUNTA(E33:R33)),"Pass","Fail") -> Pass | AH33: =COUNT(T33,">=0.5") -> 1 | AI33: =IF(AND(AG33="Pass",AH33>=0.5),"Đủ Điều kiện dự thi","Fail") -> Đủ Điều kiện dự thi | AJ33: =VLOOKUP(A33,'DSSV VIE1016'!$B$2:$D$55,3,0) -> #N/A
A34: ph16795 | B34: phuongntph16795@fpt.edu.vn | C34: phuongntph16795 | D34: 3 | E34: 1 | F34: 1 | G34: 1 | H34: 1 | I34: 1 | J34: 1 | K34: 1 | L34: 1 | M34: 1 | N34: 1 | O34: 1 | P34: 1 | Q34: 1 | R34: 1 | S34: 1 | T34: 1 | U34: 1 | V34: audit | W34: N/A | X34: N | Y34: N | Z34: N/A | AA34: enrolled | AB34: 14 | AC34: =COUNTIF(E34:R34,"Not Attempted") -> 0 | AD34: =AB34-AC34-AE34 -> 0 | AE34: =COUNTIF(E34:R34,1) -> 14 | AF34: =IF(AC34=14,"Chưa tham gia học lần nào","") | AG34: =IF(AND(MIN(E34:R34)>=1,COUNT(E34:R34)=COUNTA(E34:R34)),"Pass","Fail") -> Pass | AH34: =COUNT(T34,">=0.5") -> 1 | AI34: =IF(AND(AG34="Pass",AH34>=0.5),"Đủ Điều kiện dự thi","Fail") -> Đủ Điều kiện dự thi | AJ34: =VLOOKUP(A34,'DSSV VIE1016'!$B$2:$D$55,3,0) -> #N/A
A35: ph17614 | B35: hungxmph17614@fpt.edu.vn | C35: hungxmph17614 | D35: 3 | E35: 1 | F35: 1 | G35: 1 | H35: 1 | I35: 1 | J35: 1 | K35: 1 | L35: 1 | M35: 1 | N35: 1 | O35: 1 | P35: 1 | Q35: 1 | R35: 1 | S35: 1 | T35: 1 | U35: 1 | V35: audit | W35: N/A | X35: N | Y35: N | Z35: N/A | AA35: enrolled | AB35: 14 | AC35: =COUNTIF(E35:R35,"Not Attempted") -> 0 | AD35: =AB35-AC35-AE35 -> 0 | AE35: =COUNTIF(E35:R35,1) -> 14 | AF35: =IF(AC35=14,"Chưa tham gia học lần nào","") | AG35: =IF(AND(MIN(E35:R35)>=1,COUNT(E35:R35)=COUNTA(E35:R35)),"Pass","Fail") -> Pass | AH35: =COUNT(T35,">=0.5") -> 1 | AI35: =IF(AND(AG35="Pass",AH35>=0.5),"Đủ Điều kiện dự thi","Fail") -> Đủ Điều kiện dự thi | AJ35: =VLOOKUP(A35,'DSSV VIE1016'!$B$2:$D$55,3,0) -> #N/A
A36: pc02616 | B36: liemntpc02616@fpt.edu.vn | C36: liemntpc02616 | D36: 3 | E36: 1 | F36: 1 | G36: 1 | H36: 1 | I36: 1 | J36: 1 | K36: 1 | L36: 1 | M36: 1 | N36: 1 | O36: 1 | P36: 1 | Q36: 1 | R36: 1 | S36: 1 | T36: 1 | U36: 1 | V36: audit | W36: N/A | X36: N | Y36: N | Z36: N/A | AA36: enrolled | AB36: 14 | AC36: =COUNTIF(E36:R36,"Not Attempted") -> 0 | AD36: =AB36-AC36-AE36 -> 0 | AE36: =COUNTIF(E36:R36,1) -> 14 | AF36: =IF(AC36=14,"Chưa tham gia học lần nào","") | AG36: =IF(AND(MIN(E36:R36)>=1,COUNT(E36:R36)=COUNTA(E36:R36)),"Pass","Fail") -> Pass | AH36: =COUNT(T36,">=0.5") -> 1 | AI36: =IF(AND(AG36="Pass",AH36>=0.5),"Đủ Điều kiện dự thi","Fail") -> Đủ Điều kiện dự thi | AJ36: =VLOOKUP(A36,'DSSV VIE1016'!$B$2:$D$55,3,0) -> #N/A
A37: ph12056 | B37: nhungdtpph12056@fpt.edu.vn | C37: nhungdtpph12056 | D37: 2 | E37: 1 | F37: 1 | G37: 1 | H37: 1 | I37: 1 | J37: 1 | K37: 1 | L37: 1 | M37: 1 | N37: 1 | O37: 1 | P37: 1 | Q37: 1 | R37: 1 | S37: 1 | T37: 1 | U37: Not Attempted | V37: audit | W37: N/A | X37: N | Y37: N | Z37: N/A | AA37: enrolled | AB37: 14 | AC37: =COUNTIF(E37:R37,"Not Attempted") -> 0 | AD37: =AB37-AC37-AE37 -> 0 | AE37: =COUNTIF(E37:R37,1) -> 14 | AF37: =IF(AC37=14,"Chưa tham gia học lần nào","") | AG37: =IF(AND(MIN(E37:R37)>=1,COUNT(E37:R37)=COUNTA(E37:R37)),"Pass","Fail") -> Pass | AH37: =COUNT(T37,">=0.5") -> 1 | AI37: =IF(AND(AG37="Pass",AH37>=0.5),"Đủ Điều kiện dự thi","Fail") -> Đủ Điều kiện dự thi | AJ37: =VLOOKUP(A37,'DSSV VIE1016'!$B$2:$D$55,3,0) -> #N/A
A38: ph17229 | B38: linhctmph17229@fpt.edu.vn | C38: linhctmph17229 | D38: 3 | E38: 1 | F38: 1 | G38: 1 | H38: 1 | I38: 1 | J38: 1 | K38: 1 | L38: 1 | M38: 1 | N38: 1 | O38: 1 | P38: 1 | Q38: 1 | R38: 1 | S38: 1 | T38: 1 | U38: 1 | V38: audit | W38: N/A | X38: N | Y38: N | Z38: N/A | AA38: enrolled | AB38: 14 | AC38: =COUNTIF(E38:R38,"Not Attempted") -> 0 | AD38: =AB38-AC38-AE38 -> 0 | AE38: =COUNTIF(E38:R38,1) -> 14 | AF38: =IF(AC38=14,"Chưa tham gia học lần nào","") | AG38: =IF(AND(MIN(E38:R38)>=1,COUNT(E38:R38)=COUNTA(E38:R38)),"Pass","Fail") -> Pass | AH38: =COUNT(T38,">=0.5") -> 1 | AI38: =IF(AND(AG38="Pass",AH38>=0.5),"Đủ Điều kiện dự thi","Fail") -> Đủ Điều kiện dự thi | AJ38: =VLOOKUP(A38,'DSSV VIE1016'!$B$2:$D$55,3,0) -> #N/A
A39: ph15267 | B39: giangnhph15267@fpt.edu.vn | C39: giangnhph15267 | D39: 3 | E39: 1 | F39: 1 | G39: 1 | H39: 1 | I39: 1 | J39: 1 | K39: 1 | L39: 1 | M39: 1 | N39: 1 | O39: 1 | P39: 1 | Q39: 1 | R39: 1 | S39: 1 | T39: 1 | U39: 1 | V39: audit | W39: N/A | X39: N | Y39: N | Z39: N/A | AA39: enrolled | AB39: 14 | AC39: =COUNTIF(E39:R39,"Not Attempted") -> 0 | AD39: =AB39-AC39-AE39 -> 0 | AE39: =COUNTIF(E39:R39,1) -> 14 | AF39: =IF(AC39=14,"Chưa tham gia học lần nào","") | AG39: =IF(AND(MIN(E39:R39)>=1,COUNT(E39:R39)=COUNTA(E39:R39)),"Pass","Fail") -> Pass | AH39: =COUNT(T39,">=0.5") -> 1 | AI39: =IF(AND(AG39="Pass",AH39>=0.5),"Đủ Điều kiện dự thi","Fail") -> Đủ Điều kiện dự thi | AJ39: =VLOOKUP(A39,'DSSV VIE1016'!$B$2:$D$55,3,0) -> #N/A
A40: ph17183 | B40: huongptph17183@fpt.edu.vn | C40: huongptph17183 | D40: 3 | E40: 1 | F40: 1 | G40: 1 | H40: 1 | I40: 1 | J40: 1 | K40: 1 | L40: 1 | M40: 1 | N40: 1 | O40: 1 | P40: 1 | Q40: 1 | R40: 1 | S40: 1 | T40: 1 | U40: 1 | V40: audit | W40: N/A | X40: N | Y40: N | Z40: N/A | AA40: enrolled | AB40: 14 | AC40: =COUNTIF(E40:R40,"Not Attempted") -> 0 | AD40: =AB40-AC40-AE40 -> 0 | AE40: =COUNTIF(E40:R40,1) -> 14 | AF40: =IF(AC40=14,"Chưa tham gia học lần nào","") | AG40: =IF(AND(MIN(E40:R40)>=1,COUNT(E40:R40)=COUNTA(E40:R40)),"Pass","Fail") -> Pass | AH40: =COUNT(T40,">=0.5") -> 1 | AI40: =IF(AND(AG40="Pass",AH40>=0.5),"Đủ Điều kiện dự thi","Fail") -> Đủ Điều kiện dự thi | AJ40: =VLOOKUP(A40,'DSSV VIE1016'!$B$2:$D$55,3,0) -> #N/A
...

Sheet DSSV VIE1016
A1: STT | B1: Mã | C1: HỌ VÀ TÊN | D1: Tên lớp | E1: Mã môn | F1: å Quiz | G1: å Quiz (Chưa học) | H1: å Quiz (Đang học) | I1: å Quiz (Đã đạt) | J1: ASM (đã đạt) | K1: Chưa tham gia học | L1: Điều kiện dự thi | M1: Tiến độ học tập | N1: ngày kết thúc | O1: Tuần | P1: 44402
A2: 1 | B2: PS12765 | C2: =VLOOKUP(B2,[1]DSSV!$A:$B,2,0) -> Đào Nhật Anh | D2: CHINHTRI_05_3 | E2: VIE1016 | F2: =VLOOKUP($B2,FPOLY_VIE1016!$A$2:$AI$15000,28,0) -> 14 | G2: =VLOOKUP($B2,FPOLY_VIE1016!$A$2:$AI$15000,29,0) -> 0 | H2: =VLOOKUP($B2,FPOLY_VIE1016!$A$2:$AI$15000,30,0) -> 0 | I2: =VLOOKUP($B2,FPOLY_VIE1016!$A$2:$AI$15000,31,0) -> 14 | J2: =VLOOKUP($B2,FPOLY_VIE1016!$A$2:$AI$15000,34,0) -> 1 | K2: =VLOOKUP($B2,FPOLY_VIE1016!$A$2:$AI$15000,32,0) | L2: =VLOOKUP($B2,FPOLY_VIE1016!$A$2:$AI$15000,35,0) -> Đủ Điều kiện dự thi | M2: =IF(I2<$P2,"Chậm tiến độ","") | N2: =VLOOKUP($D2&$E2,'DS lop'!$A$2:$H$10,8,0) -> 44413 | O2: 10 | P2: 9
A3: 2 | B3: PS11760 | C3: =VLOOKUP(B3,[1]DSSV!$A:$B,2,0) -> Lê Trâm Anh | D3: CHINHTRI_05_3 | E3: VIE1016 | F3: =VLOOKUP($B3,FPOLY_VIE1016!$A$2:$AI$15000,28,0) -> 14 | G3: =VLOOKUP($B3,FPOLY_VIE1016!$A$2:$AI$15000,29,0) -> 0 | H3: =VLOOKUP($B3,FPOLY_VIE1016!$A$2:$AI$15000,30,0) -> 0 | I3: =VLOOKUP($B3,FPOLY_VIE1016!$A$2:$AI$15000,31,0) -> 14 | J3: =VLOOKUP($B3,FPOLY_VIE1016!$A$2:$AI$15000,34,0) -> 1 | K3: =VLOOKUP($B3,FPOLY_VIE1016!$A$2:$AI$15000,32,0) | L3: =VLOOKUP($B3,FPOLY_VIE1016!$A$2:$AI$15000,35,0) -> Đủ Điều kiện dự thi | M3: =IF(I3<$P3,"Chậm tiến độ","") | N3: =VLOOKUP($D3&$E3,'DS lop'!$A$2:$H$10,8,0) -> 44413 | O3: 10 | P3: 9
A4: 3 | B4: PS13434 | C4: =VLOOKUP(B4,[1]DSSV!$A:$B,2,0) -> Nguyễn Quốc Anh | D4: CHINHTRI_05_3 | E4: VIE1016 | F4: =VLOOKUP($B4,FPOLY_VIE1016!$A$2:$AI$15000,28,0) -> 14 | G4: =VLOOKUP($B4,FPOLY_VIE1016!$A$2:$AI$15000,29,0) -> 14 | H4: =VLOOKUP($B4,FPOLY_VIE1016!$A$2:$AI$15000,30,0) -> 0 | I4: =VLOOKUP($B4,FPOLY_VIE1016!$A$2:$AI$15000,31,0) -> 0 | J4: =VLOOKUP($B4,FPOLY_VIE1016!$A$2:$AI$15000,34,0) -> 0 | K4: =VLOOKUP($B4,FPOLY_VIE1016!$A$2:$AI$15000,32,0) -> Chưa tham gia học lần nào | L4: =VLOOKUP($B4,FPOLY_VIE1016!$A$2:$AI$15000,35,0) -> Fail | M4: =IF(I4<$P4,"Chậm tiến độ","") -> Chậm tiến độ | N4: =VLOOKUP($D4&$E4,'DS lop'!$A$2:$H$10,8,0) -> 44413 | O4: 10 | P4: 9
A5: 4 | B5: PS12418 | C5: =VLOOKUP(B5,[1]DSSV!$A:$B,2,0) -> Phạm Tuấn Anh | D5: CHINHTRI_05_3 | E5: VIE1016 | F5: =VLOOKUP($B5,FPOLY_VIE1016!$A$2:$AI$15000,28,0) -> 14 | G5: =VLOOKUP($B5,FPOLY_VIE1016!$A$2:$AI$15000,29,0) -> 0 | H5: =VLOOKUP($B5,FPOLY_VIE1016!$A$2:$AI$15000,30,0) -> 0 | I5: =VLOOKUP($B5,FPOLY_VIE1016!$A$2:$AI$15000,31,0) -> 14 | J5: =VLOOKUP($B5,FPOLY_VIE1016!$A$2:$AI$15000,34,0) -> 1 | K5: =VLOOKUP($B5,FPOLY_VIE1016!$A$2:$AI$15000,32,0) | L5: =VLOOKUP($B5,FPOLY_VIE1016!$A$2:$AI$15000,35,0) -> Đủ Điều kiện dự thi | M5: =IF(I5<$P5,"Chậm tiến độ","") | N5: =VLOOKUP($D5&$E5,'DS lop'!$A$2:$H$10,8,0) -> 44413 | O5: 10 | P5: 9
A6: 5 | B6: PS11640 | C6: =VLOOKUP(B6,[1]DSSV!$A:$B,2,0) -> Nguyễn Trường An | D6: CHINHTRI_05_3 | E6: VIE1016 | F6: =VLOOKUP($B6,FPOLY_VIE1016!$A$2:$AI$15000,28,0) -> 14 | G6: =VLOOKUP($B6,FPOLY_VIE1016!$A$2:$AI$15000,29,0) -> 0 | H6: =VLOOKUP($B6,FPOLY_VIE1016!$A$2:$AI$15000,30,0) -> 0 | I6: =VLOOKUP($B6,FPOLY_VIE1016!$A$2:$AI$15000,31,0) -> 14 | J6: =VLOOKUP($B6,FPOLY_VIE1016!$A$2:$AI$15000,34,0) -> 1 | K6: =VLOOKUP($B6,FPOLY_VIE1016!$A$2:$AI$15000,32,0) | L6: =VLOOKUP($B6,FPOLY_VIE1016!$A$2:$AI$15000,35,0) -> Đủ Điều kiện dự thi | M6: =IF(I6<$P6,"Chậm tiến độ","") | N6: =VLOOKUP($D6&$E6,'DS lop'!$A$2:$H$10,8,0) -> 44413 | O6: 10 | P6: 9
A7: 6 | B7: PS13500 | C7: =VLOOKUP(B7,[1]DSSV!$A:$B,2,0) -> Huỳnh Nhật Bản | D7: CHINHTRI_05_3 | E7: VIE1016 | F7: =VLOOKUP($B7,FPOLY_VIE1016!$A$2:$AI$15000,28,0) -> 14 | G7: =VLOOKUP($B7,FPOLY_VIE1016!$A$2:$AI$15000,29,0) -> 0 | H7: =VLOOKUP($B7,FPOLY_VIE1016!$A$2:$AI$15000,30,0) -> 0 | I7: =VLOOKUP($B7,FPOLY_VIE1016!$A$2:$AI$15000,31,0) -> 14 | J7: =VLOOKUP($B7,FPOLY_VIE1016!$A$2:$AI$15000,34,0) -> 1 | K7: =VLOOKUP($B7,FPOLY_VIE1016!$A$2:$AI$15000,32,0) | L7: =VLOOKUP($B7,FPOLY_VIE1016!$A$2:$AI$15000,35,0) -> Đủ Điều kiện dự thi | M7: =IF(I7<$P7,"Chậm tiến độ","") | N7: =VLOOKUP($D7&$E7,'DS lop'!$A$2:$H$10,8,0) -> 44413 | O7: 10 | P7: 9
A8: 7 | B8: PS12536 | C8: =VLOOKUP(B8,[1]DSSV!$A:$B,2,0) -> Nguyễn Gia Bảo | D8: CHINHTRI_05_3 | E8: VIE1016 | F8: =VLOOKUP($B8,FPOLY_VIE1016!$A$2:$AI$15000,28,0) -> 14 | G8: =VLOOKUP($B8,FPOLY_VIE1016!$A$2:$AI$15000,29,0) -> 0 | H8: =VLOOKUP($B8,FPOLY_VIE1016!$A$2:$AI$15000,30,0) -> 0 | I8: =VLOOKUP($B8,FPOLY_VIE1016!$A$2:$AI$15000,31,0) -> 14 | J8: =VLOOKUP($B8,FPOLY_VIE1016!$A$2:$AI$15000,34,0) -> 1 | K8: =VLOOKUP($B8,FPOLY_VIE1016!$A$2:$AI$15000,32,0) | L8: =VLOOKUP($B8,FPOLY_VIE1016!$A$2:$AI$15000,35,0) -> Đủ Điều kiện dự thi | M8: =IF(I8<$P8,"Chậm tiến độ","") | N8: =VLOOKUP($D8&$E8,'DS lop'!$A$2:$H$10,8,0) -> 44413 | O8: 10 | P8: 9
A9: 8 | B9: PS11636 | C9: =VLOOKUP(B9,[1]DSSV!$A:$B,2,0) -> Nguyễn Ngọc Bảo | D9: CHINHTRI_05_3 | E9: VIE1016 | F9: =VLOOKUP($B9,FPOLY_VIE1016!$A$2:$AI$15000,28,0) -> 14 | G9: =VLOOKUP($B9,FPOLY_VIE1016!$A$2:$AI$15000,29,0) -> 0 | H9: =VLOOKUP($B9,FPOLY_VIE1016!$A$2:$AI$15000,30,0) -> 0 | I9: =VLOOKUP($B9,FPOLY_VIE1016!$A$2:$AI$15000,31,0) -> 14 | J9: =VLOOKUP($B9,FPOLY_VIE1016!$A$2:$AI$15000,34,0) -> 1 | K9: =VLOOKUP($B9,FPOLY_VIE1016!$A$2:$AI$15000,32,0) | L9: =VLOOKUP($B9,FPOLY_VIE1016!$A$2:$AI$15000,35,0) -> Đủ Điều kiện dự thi | M9: =IF(I9<$P9,"Chậm tiến độ","") | N9: =VLOOKUP($D9&$E9,'DS lop'!$A$2:$H$10,8,0) -> 44413 | O9: 10 | P9: 9
A10: 9 | B10: PS12694 | C10: =VLOOKUP(B10,[1]DSSV!$A:$B,2,0) -> Nguyễn Phan Gia Bảo | D10: CHINHTRI_05_3 | E10: VIE1016 | F10: =VLOOKUP($B10,FPOLY_VIE1016!$A$2:$AI$15000,28,0) -> 14 | G10: =VLOOKUP($B10,FPOLY_VIE1016!$A$2:$AI$15000,29,0) -> 0 | H10: =VLOOKUP($B10,FPOLY_VIE1016!$A$2:$AI$15000,30,0) -> 0 | I10: =VLOOKUP($B10,FPOLY_VIE1016!$A$2:$AI$15000,31,0) -> 14 | J10: =VLOOKUP($B10,FPOLY_VIE1016!$A$2:$AI$15000,34,0) -> 1 | K10: =VLOOKUP($B10,FPOLY_VIE1016!$A$2:$AI$15000,32,0) | L10: =VLOOKUP($B10,FPOLY_VIE1016!$A$2:$AI$15000,35,0) -> Đủ Điều kiện dự thi | M10: =IF(I10<$P10,"Chậm tiến độ","") | N10: =VLOOKUP($D10&$E10,'DS lop'!$A$2:$H$10,8,0) -> 44413 | O10: 10 | P10: 9
A11: 10 | B11: PS13363 | C11: =VLOOKUP(B11,[1]DSSV!$A:$B,2,0) -> Nguyễn Thanh Bình | D11: CHINHTRI_05_3 | E11: VIE1016 | F11: =VLOOKUP($B11,FPOLY_VIE1016!$A$2:$AI$15000,28,0) -> 14 | G11: =VLOOKUP($B11,FPOLY_VIE1016!$A$2:$AI$15000,29,0) -> 0 | H11: =VLOOKUP($B11,FPOLY_VIE1016!$A$2:$AI$15000,30,0) -> 0 | I11: =VLOOKUP($B11,FPOLY_VIE1016!$A$2:$AI$15000,31,0) -> 14 | J11: =VLOOKUP($B11,FPOLY_VIE1016!$A$2:$AI$15000,34,0) -> 1 | K11: =VLOOKUP($B11,FPOLY_VIE1016!$A$2:$AI$15000,32,0) | L11: =VLOOKUP($B11,FPOLY_VIE1016!$A$2:$AI$15000,35,0) -> Đủ Điều kiện dự thi | M11: =IF(I11<$P11,"Chậm tiến độ","") | N11: =VLOOKUP($D11&$E11,'DS lop'!$A$2:$H$10,8,0) -> 44413 | O11: 10 | P11: 9
A12: 11 | B12: PS14145 | C12: =VLOOKUP(B12,[1]DSSV!$A:$B,2,0) -> Trần Hải Bình | D12: CHINHTRI_05_3 | E12: VIE1016 | F12: =VLOOKUP($B12,FPOLY_VIE1016!$A$2:$AI$15000,28,0) -> 14 | G12: =VLOOKUP($B12,FPOLY_VIE1016!$A$2:$AI$15000,29,0) -> 0 | H12: =VLOOKUP($B12,FPOLY_VIE1016!$A$2:$AI$15000,30,0) -> 0 | I12: =VLOOKUP($B12,FPOLY_VIE1016!$A$2:$AI$15000,31,0) -> 14 | J12: =VLOOKUP($B12,FPOLY_VIE1016!$A$2:$AI$15000,34,0) -> 1 | K12: =VLOOKUP($B12,FPOLY_VIE1016!$A$2:$AI$15000,32,0) | L12: =VLOOKUP($B12,FPOLY_VIE1016!$A$2:$AI$15000,35,0) -> Đủ Điều kiện dự thi | M12: =IF(I12<$P12,"Chậm tiến độ","") | N12: =VLOOKUP($D12&$E12,'DS lop'!$A$2:$H$10,8,0) -> 44413 | O12: 10 | P12: 9
A13: 12 | B13: PS13531 | C13: =VLOOKUP(B13,[1]DSSV!$A:$B,2,0) -> Trần Lê Phúc Bình | D13: CHINHTRI_05_3 | E13: VIE1016 | F13: =VLOOKUP($B13,FPOLY_VIE1016!$A$2:$AI$15000,28,0) -> 14 | G13: =VLOOKUP($B13,FPOLY_VIE1016!$A$2:$AI$15000,29,0) -> 0 | H13: =VLOOKUP($B13,FPOLY_VIE1016!$A$2:$AI$15000,30,0) -> 0 | I13: =VLOOKUP($B13,FPOLY_VIE1016!$A$2:$AI$15000,31,0) -> 14 | J13: =VLOOKUP($B13,FPOLY_VIE1016!$A$2:$AI$15000,34,0) -> 1 | K13: =VLOOKUP($B13,FPOLY_VIE1016!$A$2:$AI$15000,32,0) | L13: =VLOOKUP($B13,FPOLY_VIE1016!$A$2:$AI$15000,35,0) -> Đủ Điều kiện dự thi | M13: =IF(I13<$P13,"Chậm tiến độ","") | N13: =VLOOKUP($D13&$E13,'DS lop'!$A$2:$H$10,8,0) -> 44413 | O13: 10 | P13: 9
... A819: 818 | B819: PS14598 | C819: =VLOOKUP(B819,[1]DSSV!$A:$B,2,0) -> Nguyễn Thị Xuân Yến | D819: CHINHTRI_03_2 | E819: VIE1016 | F819: =VLOOKUP($B819,FPOLY_VIE1016!$A$2:$AI$15000,28,0) -> 14 | G819: =VLOOKUP($B819,FPOLY_VIE1016!$A$2:$AI$15000,29,0) -> 0 | H819: =VLOOKUP($B819,FPOLY_VIE1016!$A$2:$AI$15000,30,0) -> 0 | I819: =VLOOKUP($B819,FPOLY_VIE1016!$A$2:$AI$15000,31,0) -> 14 | J819: =VLOOKUP($B819,FPOLY_VIE1016!$A$2:$AI$15000,34,0) -> 0 | K819: =VLOOKUP($B819,FPOLY_VIE1016!$A$2:$AI$15000,32,0) | L819: =VLOOKUP($B819,FPOLY_VIE1016!$A$2:$AI$15000,35,0) -> Fail | M819: =IF(I819<$P819,"Chậm tiến độ","") | N819: =VLOOKUP($D819&$E819,'DS lop'!$A$2:$H$10,8,0) -> 44417 | O819: 10 | P819: 9

Sheet Tke lop mon
A1: THỐNG KÊ TÌNH HÌNH HỌC ONLINE
A2: MÔN: | C2: VIE1016 | J2: =J3*100/G3 -> 75.764994
A3: Cơ sở | C3: HCM | G3: =SUM(G5:G107) -> 817 | H3: =SUM(H5:H107) -> 7 | I3: =SUM(I5:I107) -> 191 | J3: =SUM(J5:J107) -> 619 | K3: =H3/G3 -> 0.0085679315 | L3: =SUM(L5:L107) -> 84 | M3: =L3/G3 -> 0.10281518
A4: STT | B4: Môn | C4: Lớp | D4: Giảng viên | E4: Ngày bắt đầu học | F4: Ngày kết thúc | G4: å Sinh viên | H4: å Sinh viên (Chưa học) | I4: å Sinh viên (Đang học) | J4: å Sinh viên (Đủ điều kiện thi) | K4: Tỷ lệ (chưa tham dự học) | L4: å Sinh viên (Chậm tiến độ) | M4: Tỷ lệ (Chậm tiến độ) | N4: Quiz hoàn thành theo tiến độ
A5: 1 | B5: VIE1016 | C5: CHINHTRI_03_3 | D5: huongltm | E5: 44375 | F5: 44412 | G5: 90 | H5: =COUNTIFS('DSSV VIE1016'!$D:$D,C5,'DSSV VIE1016'!$G:$G,8) -> 1 | I5: =G5-H5-J5 -> 18 | J5: =COUNTIFS('DSSV VIE1016'!$D:$D,'Tke lop mon'!C5,'DSSV VIE1016'!$L:$L,"Đủ Điều kiện dự thi") -> 71 | K5: =IF(G5=H5,"Chưa có sv tham dự học",H5/G5) -> 0.011111111 | L5: =COUNTIFS('DSSV VIE1016'!$D:$D,'Tke lop mon'!C5,'DSSV VIE1016'!$M:$M,"Chậm tiến độ") -> 9 | M5: =L5/G5 -> 0.1 | N5: =VLOOKUP(Table2[[#This Row],[Lớp]],'DSSV VIE1016'!$D$2:$P$998,13,0) -> 9
A6: 2 | B6: VIE1016 | C6: CHINHTRI_05_3 | D6: trangptt42 | E6: 44376 | F6: 44413 | G6: 98 | H6: =COUNTIFS('DSSV VIE1016'!$D:$D,C6,'DSSV VIE1016'!$G:$G,8) -> 1 | I6: =G6-H6-J6 -> 26 | J6: =COUNTIFS('DSSV VIE1016'!$D:$D,'Tke lop mon'!C6,'DSSV VIE1016'!$L:$L,"Đủ Điều kiện dự thi") -> 71 | K6: =IF(G6=H6,"Chưa có sv tham dự học",H6/G6) -> 0.010204082 | L6: =COUNTIFS('DSSV VIE1016'!$D:$D,'Tke lop mon'!C6,'DSSV VIE1016'!$M:$M,"Chậm tiến độ") -> 11 | M6: =L6/G6 -> 0.1122449 | N6: =VLOOKUP(Table2[[#This Row],[Lớp]],'DSSV VIE1016'!$D$2:$P$998,13,0) -> 9
A7: 3 | B7: VIE1016 | C7: CHINHTRI_01_3 | D7: trangptt42 | E7: 44377 | F7: 44414 | G7: 88 | H7: =COUNTIFS('DSSV VIE1016'!$D:$D,C7,'DSSV VIE1016'!$G:$G,8) -> 0 | I7: =G7-H7-J7 -> 19 | J7: =COUNTIFS('DSSV VIE1016'!$D:$D,'Tke lop mon'!C7,'DSSV VIE1016'!$L:$L,"Đủ Điều kiện dự thi") -> 69 | K7: =IF(G7=H7,"Chưa có sv tham dự học",H7/G7) -> 0 | L7: =COUNTIFS('DSSV VIE1016'!$D:$D,'Tke lop mon'!C7,'DSSV VIE1016'!$M:$M,"Chậm tiến độ") -> 6 | M7: =L7/G7 -> 0.068181818 | N7: =VLOOKUP(Table2[[#This Row],[Lớp]],'DSSV VIE1016'!$D$2:$P$998,13,0) -> 9
A8: 4 | B8: VIE1016 | C8: CHINHTRI_06_3 | D8: trangptt42 | E8: 44377 | F8: 44414 | G8: 101 | H8: =COUNTIFS('DSSV VIE1016'!$D:$D,C8,'DSSV VIE1016'!$G:$G,8) -> 2 | I8: =G8-H8-J8 -> 31 | J8: =COUNTIFS('DSSV VIE1016'!$D:$D,'Tke lop mon'!C8,'DSSV VIE1016'!$L:$L,"Đủ Điều kiện dự thi") -> 68 | K8: =IF(G8=H8,"Chưa có sv tham dự học",H8/G8) -> 0.01980198 | L8: =COUNTIFS('DSSV VIE1016'!$D:$D,'Tke lop mon'!C8,'DSSV VIE1016'!$M:$M,"Chậm tiến độ") -> 8 | M8: =L8/G8 -> 0.079207921 | N8: =VLOOKUP(Table2[[#This Row],[Lớp]],'DSSV VIE1016'!$D$2:$P$998,13,0) -> 9
A9: 5 | B9: VIE1016 | C9: CHINHTRI_02_3 | D9: huongltm | E9: 44378 | F9: 44415 | G9: 98 | H9: =COUNTIFS('DSSV VIE1016'!$D:$D,C9,'DSSV VIE1016'!$G:$G,8) -> 0 | I9: =G9-H9-J9 -> 18 | J9: =COUNTIFS('DSSV VIE1016'!$D:$D,'Tke lop mon'!C9,'DSSV VIE1016'!$L:$L,"Đủ Điều kiện dự thi") -> 80 | K9: =IF(G9=H9,"Chưa có sv tham dự học",H9/G9) -> 0 | L9: =COUNTIFS('DSSV VIE1016'!$D:$D,'Tke lop mon'!C9,'DSSV VIE1016'!$M:$M,"Chậm tiến độ") -> 13 | M9: =L9/G9 -> 0.13265306 | N9: =VLOOKUP(Table2[[#This Row],[Lớp]],'DSSV VIE1016'!$D$2:$P$998,13,0) -> 9
A10: 6 | B10: VIE1016 | C10: CHINHTRI_04_3 | D10: huongltm | E10: 44379 | F10: 44417 | G10: 88 | H10: =COUNTIFS('DSSV VIE1016'!$D:$D,C10,'DSSV VIE1016'!$G:$G,8) -> 0 | I10: =G10-H10-J10 -> 10 | J10: =COUNTIFS('DSSV VIE1016'!$D:$D,'Tke lop mon'!C10,'DSSV VIE1016'!$L:$L,"Đủ Điều kiện dự thi") -> 78 | K10: =IF(G10=H10,"Chưa có sv tham dự học",H10/G10) -> 0 | L10: =COUNTIFS('DSSV VIE1016'!$D:$D,'Tke lop mon'!C10,'DSSV VIE1016'!$M:$M,"Chậm tiến độ") -> 5 | M10: =L10/G10 -> 0.056818182 | N10: =VLOOKUP(Table2[[#This Row],[Lớp]],'DSSV VIE1016'!$D$2:$P$998,13,0) -> 9
A11: 7 | B11: VIE1016 | C11: CHINHTRI_01_2 | D11: huongltm | E11: 44379 | F11: 44417 | G11: 82 | H11: =COUNTIFS('DSSV VIE1016'!$D:$D,C11,'DSSV VIE1016'!$G:$G,8) -> 0 | I11: =G11-H11-J11 -> 8 | J11: =COUNTIFS('DSSV VIE1016'!$D:$D,'Tke lop mon'!C11,'DSSV VIE1016'!$L:$L,"Đủ Điều kiện dự thi") -> 74 | K11: =IF(G11=H11,"Chưa có sv tham dự học",H11/G11) -> 0 | L11: =COUNTIFS('DSSV VIE1016'!$D:$D,'Tke lop mon'!C11,'DSSV VIE1016'!$M:$M,"Chậm tiến độ") -> 5 | M11: =L11/G11 -> 0.06097561 | N11: =VLOOKUP(Table2[[#This Row],[Lớp]],'DSSV VIE1016'!$D$2:$P$998,13,0) -> 9
A12: 8 | B12: VIE1016 | C12: CHINHTRI_02_2 | D12: trangptt42 | E12: 44379 | F12: 44417 | G12: 91 | H12: =COUNTIFS('DSSV VIE1016'!$D:$D,C12,'DSSV VIE1016'!$G:$G,8) -> 1 | I12: =G12-H12-J12 -> 43 | J12: =COUNTIFS('DSSV VIE1016'!$D:$D,'Tke lop mon'!C12,'DSSV VIE1016'!$L:$L,"Đủ Điều kiện dự thi") -> 47 | K12: =IF(G12=H12,"Chưa có sv tham dự học",H12/G12) -> 0.010989011 | L12: =COUNTIFS('DSSV VIE1016'!$D:$D,'Tke lop mon'!C12,'DSSV VIE1016'!$M:$M,"Chậm tiến độ") -> 17 | M12: =L12/G12 -> 0.18681319 | N12: =VLOOKUP(Table2[[#This Row],[Lớp]],'DSSV VIE1016'!$D$2:$P$998,13,0) -> 9
A13: 9 | B13: VIE1016 | C13: CHINHTRI_03_2 | D13: huongltm | E13: 44379 | F13: 44417 | G13: 81 | H13: =COUNTIFS('DSSV VIE1016'!$D:$D,C13,'DSSV VIE1016'!$G:$G,8) -> 2 | I13: =G13-H13-J13 -> 18 | J13: =COUNTIFS('DSSV VIE1016'!$D:$D,'Tke lop mon'!C13,'DSSV VIE1016'!$L:$L,"Đủ Điều kiện dự thi") -> 61 | K13: =IF(G13=H13,"Chưa có sv tham dự học",H13/G13) -> 0.024691358 | L13: =COUNTIFS('DSSV VIE1016'!$D:$D,'Tke lop mon'!C13,'DSSV VIE1016'!$M:$M,"Chậm tiến độ") -> 10 | M13: =L13/G13 -> 0.12345679 | N13: =VLOOKUP(Table2[[#This Row],[Lớp]],'DSSV VIE1016'!$D$2:$P$998,13,0) -> 9

Sheet Tke GV
A1: THỐNG KÊ GIẢNG VIÊN
B2: å Lớp | C2: å Sinh viên | D2: å Sinh viên (Chưa học) | E2: å Sinh viên (Đang học) | F2: å Sinh viên (Đủ điều kiện thi) | G2: Tỷ lệ (chưa tham dự học) | H2: å Sinh viên (Chậm tiến độ) | I2: Tỷ lệ (Chậm tiến độ)
A3: huongltm | B3: =COUNTIF('Tke lop mon'!$D:$D,'Tke GV'!$A3) -> 5 | C3: =SUMIF('Tke lop mon'!$D:$D,'Tke GV'!$A3,'Tke lop mon'!G:G) -> 439 | D3: =SUMIF('Tke lop mon'!$D:$D,'Tke GV'!$A3,'Tke lop mon'!H:H) -> 3 | E3: =SUMIF('Tke lop mon'!$D:$D,'Tke GV'!$A3,'Tke lop mon'!I:I) -> 72 | F3: =SUMIF('Tke lop mon'!$D:$D,'Tke GV'!$A3,'Tke lop mon'!J:J) -> 364 | G3: =IF(C3=D3,"Chưa có sv tham dự học",D3/C3) -> 0.006833713 | H3: =SUMIF('Tke lop mon'!$D:$D,'Tke GV'!$A3,'Tke lop mon'!L:L) -> 42 | I3: =H3/C3 -> 0.095671982
A4: trangptt42 | B4: =COUNTIF('Tke lop mon'!$D:$D,'Tke GV'!$A4) -> 4 | C4: =SUMIF('Tke lop mon'!$D:$D,'Tke GV'!$A4,'Tke lop mon'!G:G) -> 378 | D4: =SUMIF('Tke lop mon'!$D:$D,'Tke GV'!$A4,'Tke lop mon'!H:H) -> 4 | E4: =SUMIF('Tke lop mon'!$D:$D,'Tke GV'!$A4,'Tke lop mon'!I:I) -> 119 | F4: =SUMIF('Tke lop mon'!$D:$D,'Tke GV'!$A4,'Tke lop mon'!J:J) -> 255 | G4: =IF(C4=D4,"Chưa có sv tham dự học",D4/C4) -> 0.010582011 | H4: =SUMIF('Tke lop mon'!$D:$D,'Tke GV'!$A4,'Tke lop mon'!L:L) -> 42 | I4: =H4/C4 -> 0.11111111
A5: Total | B5: =SUM(B3:B3) -> 5 | C5: =SUM(C3:C3) -> 439 | D5: =SUM(D3:D3) -> 3 | E5: =SUM(E3:E3) -> 72 | F5: =SUM(F3:F3) -> 364 | G5: =IF(C5=D5,"Chưa có sv tham dự học",D5/C5) -> 0.006833713 | H5: =SUM(H3:H3) -> 42 | I5: =H5/C5 -> 0.095671982

Sheet DS lop
A1: TT | B1: Lớp | C1: Mã môn | D1: Môn | E1: GV | F1: SL | G1: Ngày bắt đầu | H1: Ngày kết thúc
A2: =B2&C2 -> CHINHTRI_03_3VIE1016 | B2: CHINHTRI_03_3 | C2: VIE1016 | D2: Chính trị | E2: huongltm | F2: 90 | G2: 44375 | H2: 44412
A3: =B3&C3 -> CHINHTRI_05_3VIE1016 | B3: CHINHTRI_05_3 | C3: VIE1016 | D3: Chính trị | E3: trangptt42 | F3: 98 | G3: 44376 | H3: 44413
A4: =B4&C4 -> CHINHTRI_01_3VIE1016 | B4: CHINHTRI_01_3 | C4: VIE1016 | D4: Chính trị | E4: trangptt42 | F4: 88 | G4: 44377 | H4: 44414
A5: =B5&C5 -> CHINHTRI_06_3VIE1016 | B5: CHINHTRI_06_3 | C5: VIE1016 | D5: Chính trị | E5: trangptt42 | F5: 101 | G5: 44377 | H5: 44414
A6: =B6&C6 -> CHINHTRI_02_3VIE1016 | B6: CHINHTRI_02_3 | C6: VIE1016 | D6: Chính trị | E6: huongltm | F6: 98 | G6: 44378 | H6: 44415
A7: =B7&C7 -> CHINHTRI_04_3VIE1016 | B7: CHINHTRI_04_3 | C7: VIE1016 | D7: Chính trị | E7: huongltm | F7: 88 | G7: 44379 | H7: 44417
A8: =B8&C8 -> CHINHTRI_01_2VIE1016 | B8: CHINHTRI_01_2 | C8: VIE1016 | D8: Chính trị | E8: huongltm | F8: 82 | G8: 44379 | H8: 44417
A9: =B9&C9 -> CHINHTRI_02_2VIE1016 | B9: CHINHTRI_02_2 | C9: VIE1016 | D9: Chính trị | E9: trangptt42 | F9: 91 | G9: 44379 | H9: 44417
A10: =B10&C10 -> CHINHTRI_03_2VIE1016 | B10: CHINHTRI_03_2 | C10: VIE1016 | D10: Chính trị | E10: huongltm | F10: 81 | G10: 44379 | H10: 44417

Sheet Ke hoach
A1: TT | B1: Môn | C1: Mã môn | D1: BM | E1: Tuần 8 (Block 2) | F1: Nghỉ hè | G1: Tuần 9 | H1: Tuần 10 | I1: Tuần 11 | J1: Tuần 12 | K1: Tuần 13 | L1: Tuần 14 | M1: 8 | N1: 9 | O1: 10 | P1: 11 | Q1: 12 | R1: 13 | S1: 14 | T1: 15
B2: từ ngày làm Quiz | E2: 44375 | F2: 44382 | G2: 44389 | H2: 44396 | I2: 44403 | J2: 44410 | K2: 44417 | L2: 44424 | M2: =E2 -> 44375 | N2: =F2 -> 44382 | O2: =G2 -> 44389 | P2: =H2 -> 44396 | Q2: =I2 -> 44403 | R2: =J2 -> 44410 | S2: =K2 -> 44417 | T2: =L2 -> 44424
B3: đến deadline hoàn thành Quiz | E3: 44381 | F3: 44388 | G3: 44395 | H3: 44402 | I3: 44409 | J3: 44416 | K3: 44423 | L3: 44430 | M3: =E3 -> 44381 | N3: =F3 -> 44388 | O3: =G3 -> 44395 | P3: =H3 -> 44402 | Q3: =I3 -> 44409 | R3: =J3 -> 44416 | S3: =K3 -> 44423 | T3: =L3 -> 44430
A4: 1 | B4: Tiếng Anh 1.1 | C4: ENT1125 | D4: CB | E4: Quiz 1 | F4: Quiz 2 | G4: Quiz 3 | H4: Quiz 4 | I4: Quiz 5 | J4: Quiz 6 | K4: Quiz 7 | L4: Quiz 8 | M4: =IFERROR(MID(RIGHT(E4,2),FIND("-",RIGHT(E4,2),1)+1,2),TRIM(RIGHT(E4,2))) -> 1 | N4: =IFERROR(MID(RIGHT(F4,2),FIND("-",RIGHT(F4,2),1)+1,2),TRIM(RIGHT(F4,2))) -> 2 | O4: =IFERROR(MID(RIGHT(G4,2),FIND("-",RIGHT(G4,2),1)+1,2),TRIM(RIGHT(G4,2))) -> 3 | P4: =IFERROR(MID(RIGHT(H4,2),FIND("-",RIGHT(H4,2),1)+1,2),TRIM(RIGHT(H4,2))) -> 4 | Q4: =IFERROR(MID(RIGHT(I4,2),FIND("-",RIGHT(I4,2),1)+1,2),TRIM(RIGHT(I4,2))) -> 5 | R4: =IFERROR(MID(RIGHT(J4,2),FIND("-",RIGHT(J4,2),1)+1,2),TRIM(RIGHT(J4,2))) -> 6 | S4: =IFERROR(MID(RIGHT(K4,2),FIND("-",RIGHT(K4,2),1)+1,2),TRIM(RIGHT(K4,2))) -> 7 | T4: =IFERROR(MID(RIGHT(L4,2),FIND("-",RIGHT(L4,2),1)+1,2),TRIM(RIGHT(L4,2))) -> 8
A5: 2 | B5: Tiếng Anh 1.2 | C5: ENT1225 | D5: CB | E5: Quiz 1 | F5: Quiz 2 | G5: Quiz 3 | H5: Quiz 4 | I5: Quiz 5 | J5: Quiz 6 | K5: Quiz 7 | L5: Quiz 8 | M5: =IFERROR(MID(RIGHT(E5,2),FIND("-",RIGHT(E5,2),1)+1,2),TRIM(RIGHT(E5,2))) -> 1 | N5: =IFERROR(MID(RIGHT(F5,2),FIND("-",RIGHT(F5,2),1)+1,2),TRIM(RIGHT(F5,2))) -> 2 | O5: =IFERROR(MID(RIGHT(G5,2),FIND("-",RIGHT(G5,2),1)+1,2),TRIM(RIGHT(G5,2))) -> 3 | P5: =IFERROR(MID(RIGHT(H5,2),FIND("-",RIGHT(H5,2),1)+1,2),TRIM(RIGHT(H5,2))) -> 4 | Q5: =IFERROR(MID(RIGHT(I5,2),FIND("-",RIGHT(I5,2),1)+1,2),TRIM(RIGHT(I5,2))) -> 5 | R5: =IFERROR(MID(RIGHT(J5,2),FIND("-",RIGHT(J5,2),1)+1,2),TRIM(RIGHT(J5,2))) -> 6 | S5: =IFERROR(MID(RIGHT(K5,2),FIND("-",RIGHT(K5,2),1)+1,2),TRIM(RIGHT(K5,2))) -> 7 | T5: =IFERROR(MID(RIGHT(L5,2),FIND("-",RIGHT(L5,2),1)+1,2),TRIM(RIGHT(L5,2))) -> 8
A6: 3 | B6: Tiếng Anh 2.1 | C6: ENT2125 | D6: CB | E6: Quiz 1 | F6: Quiz 2 | G6: Quiz 3 | H6: Quiz 4 | I6: Quiz 5 | J6: Quiz 6 | K6: Quiz 7 | L6: Quiz 8 | M6: =IFERROR(MID(RIGHT(E6,2),FIND("-",RIGHT(E6,2),1)+1,2),TRIM(RIGHT(E6,2))) -> 1 | N6: =IFERROR(MID(RIGHT(F6,2),FIND("-",RIGHT(F6,2),1)+1,2),TRIM(RIGHT(F6,2))) -> 2 | O6: =IFERROR(MID(RIGHT(G6,2),FIND("-",RIGHT(G6,2),1)+1,2),TRIM(RIGHT(G6,2))) -> 3 | P6: =IFERROR(MID(RIGHT(H6,2),FIND("-",RIGHT(H6,2),1)+1,2),TRIM(RIGHT(H6,2))) -> 4 | Q6: =IFERROR(MID(RIGHT(I6,2),FIND("-",RIGHT(I6,2),1)+1,2),TRIM(RIGHT(I6,2))) -> 5 | R6: =IFERROR(MID(RIGHT(J6,2),FIND("-",RIGHT(J6,2),1)+1,2),TRIM(RIGHT(J6,2))) -> 6 | S6: =IFERROR(MID(RIGHT(K6,2),FIND("-",RIGHT(K6,2),1)+1,2),TRIM(RIGHT(K6,2))) -> 7 | T6: =IFERROR(MID(RIGHT(L6,2),FIND("-",RIGHT(L6,2),1)+1,2),TRIM(RIGHT(L6,2))) -> 8
A7: 4 | B7: Tiếng Anh 2.2 | C7: ENT2225 | D7: CB | E7: Quiz 1 | F7: Quiz 2 | G7: Quiz 3 | H7: Quiz 4 | I7: Quiz 5 | J7: Quiz 6 | K7: Quiz 7 | L7: Quiz 8 | M7: =IFERROR(MID(RIGHT(E7,2),FIND("-",RIGHT(E7,2),1)+1,2),TRIM(RIGHT(E7,2))) -> 1 | N7: =IFERROR(MID(RIGHT(F7,2),FIND("-",RIGHT(F7,2),1)+1,2),TRIM(RIGHT(F7,2))) -> 2 | O7: =IFERROR(MID(RIGHT(G7,2),FIND("-",RIGHT(G7,2),1)+1,2),TRIM(RIGHT(G7,2))) -> 3 | P7: =IFERROR(MID(RIGHT(H7,2),FIND("-",RIGHT(H7,2),1)+1,2),TRIM(RIGHT(H7,2))) -> 4 | Q7: =IFERROR(MID(RIGHT(I7,2),FIND("-",RIGHT(I7,2),1)+1,2),TRIM(RIGHT(I7,2))) -> 5 | R7: =IFERROR(MID(RIGHT(J7,2),FIND("-",RIGHT(J7,2),1)+1,2),TRIM(RIGHT(J7,2))) -> 6 | S7: =IFERROR(MID(RIGHT(K7,2),FIND("-",RIGHT(K7,2),1)+1,2),TRIM(RIGHT(K7,2))) -> 7 | T7: =IFERROR(MID(RIGHT(L7,2),FIND("-",RIGHT(L7,2),1)+1,2),TRIM(RIGHT(L7,2))) -> 8
A8: 5 | B8: Chính trị | C8: VIE1016 | D8: CB | E8: Quiz 1-3 | F8: Quiz 4-6 | G8: Quiz 7-9 | H8: Quiz 10-12 | I8: Quiz 13-14 | J8: Ôn + Thi | L8: Quiz 1-3 | M8: =IFERROR(MID(RIGHT(E8,2),FIND("-",RIGHT(E8,2),1)+1,2),TRIM(RIGHT(E8,2))) -> 3 | N8: =IFERROR(MID(RIGHT(F8,2),FIND("-",RIGHT(F8,2),1)+1,2),TRIM(RIGHT(F8,2))) -> 6 | O8: =IFERROR(MID(RIGHT(G8,2),FIND("-",RIGHT(G8,2),1)+1,2),TRIM(RIGHT(G8,2))) -> 9 | P8: =IFERROR(MID(RIGHT(H8,2),FIND("-",RIGHT(H8,2),1)+1,2),TRIM(RIGHT(H8,2))) -> 12 | Q8: =IFERROR(MID(RIGHT(I8,2),FIND("-",RIGHT(I8,2),1)+1,2),TRIM(RIGHT(I8,2))) -> 14 | R8: =IFERROR(MID(RIGHT(J8,2),FIND("-",RIGHT(J8,2),1)+1,2),TRIM(RIGHT(J8,2))) -> hi | S8: =IFERROR(MID(RIGHT(K8,2),FIND("-",RIGHT(K8,2),1)+1,2),TRIM(RIGHT(K8,2))) | T8: =IFERROR(MID(RIGHT(L8,2),FIND("-",RIGHT(L8,2),1)+1,2),TRIM(RIGHT(L8,2))) -> 3
A9: 6 | B9: Pháp luật | C9: VIE1026 | D9: CB | E9: Quiz 1-3 | G9: Quiz 4-6 | H9: Quiz 7-9 | I9: Quiz 10-12 | J9: Quiz 13-14 | K9: Ôn + Thi | M9: =IFERROR(MID(RIGHT(E9,2),FIND("-",RIGHT(E9,2),1)+1,2),TRIM(RIGHT(E9,2))) -> 3 | N9: =IFERROR(MID(RIGHT(F9,2),FIND("-",RIGHT(F9,2),1)+1,2),TRIM(RIGHT(F9,2))) | O9: =IFERROR(MID(RIGHT(G9,2),FIND("-",RIGHT(G9,2),1)+1,2),TRIM(RIGHT(G9,2))) -> 6 | P9: =IFERROR(MID(RIGHT(H9,2),FIND("-",RIGHT(H9,2),1)+1,2),TRIM(RIGHT(H9,2))) -> 9 | Q9: =IFERROR(MID(RIGHT(I9,2),FIND("-",RIGHT(I9,2),1)+1,2),TRIM(RIGHT(I9,2))) -> 12 | R9: =IFERROR(MID(RIGHT(J9,2),FIND("-",RIGHT(J9,2),1)+1,2),TRIM(RIGHT(J9,2))) -> 14 | S9: =IFERROR(MID(RIGHT(K9,2),FIND("-",RIGHT(K9,2),1)+1,2),TRIM(RIGHT(K9,2))) -> hi | T9: =IFERROR(MID(RIGHT(L9,2),FIND("-",RIGHT(L9,2),1)+1,2),TRIM(RIGHT(L9,2)))
A10: 7 | B10: Tin học | C10: COM107 | D10: CNTT | E10: Quiz 1-2 | F10: Quiz 3 | G10: Quiz 4 | H10: Quiz 5-6 | I10: Quiz 7 | J10: Quiz 8 | K10: Ôn + Thi | L10: Quiz 1-2 | M10: =IFERROR(MID(RIGHT(E10,2),FIND("-",RIGHT(E10,2),1)+1,2),TRIM(RIGHT(E10,2))) -> 2 | N10: =IFERROR(MID(RIGHT(F10,2),FIND("-",RIGHT(F10,2),1)+1,2),TRIM(RIGHT(F10,2))) -> 3 | O10: =IFERROR(MID(RIGHT(G10,2),FIND("-",RIGHT(G10,2),1)+1,2),TRIM(RIGHT(G10,2))) -> 4 | P10: =IFERROR(MID(RIGHT(H10,2),FIND("-",RIGHT(H10,2),1)+1,2),TRIM(RIGHT(H10,2))) -> 6 | Q10: =IFERROR(MID(RIGHT(I10,2),FIND("-",RIGHT(I10,2),1)+1,2),TRIM(RIGHT(I10,2))) -> 7 | R10: =IFERROR(MID(RIGHT(J10,2),FIND("-",RIGHT(J10,2),1)+1,2),TRIM(RIGHT(J10,2))) -> 8 | S10: =IFERROR(MID(RIGHT(K10,2),FIND("-",RIGHT(K10,2),1)+1,2),TRIM(RIGHT(K10,2))) -> hi | T10: =IFERROR(MID(RIGHT(L10,2),FIND("-",RIGHT(L10,2),1)+1,2),TRIM(RIGHT(L10,2))) -> 2
A11: 8 | B11: Thiết kế web với HTML5&CSS3 | C11: WEB3023 | D11: CNTT | E11: Quiz 1-2 | F11: Quiz 3 | G11: Quiz 4 | H11: Quiz 5-6 | I11: Quiz 7 | J11: Quiz 8 | K11: Ôn + Thi | L11: Quiz 1-2 | M11: =IFERROR(MID(RIGHT(E11,2),FIND("-",RIGHT(E11,2),1)+1,2),TRIM(RIGHT(E11,2))) -> 2 | N11: =IFERROR(MID(RIGHT(F11,2),FIND("-",RIGHT(F11,2),1)+1,2),TRIM(RIGHT(F11,2))) -> 3 | O11: =IFERROR(MID(RIGHT(G11,2),FIND("-",RIGHT(G11,2),1)+1,2),TRIM(RIGHT(G11,2))) -> 4 | P11: =IFERROR(MID(RIGHT(H11,2),FIND("-",RIGHT(H11,2),1)+1,2),TRIM(RIGHT(H11,2))) -> 6 | Q11: =IFERROR(MID(RIGHT(I11,2),FIND("-",RIGHT(I11,2),1)+1,2),TRIM(RIGHT(I11,2))) -> 7 | R11: =IFERROR(MID(RIGHT(J11,2),FIND("-",RIGHT(J11,2),1)+1,2),TRIM(RIGHT(J11,2))) -> 8 | S11: =IFERROR(MID(RIGHT(K11,2),FIND("-",RIGHT(K11,2),1)+1,2),TRIM(RIGHT(K11,2))) -> hi | T11: =IFERROR(MID(RIGHT(L11,2),FIND("-",RIGHT(L11,2),1)+1,2),TRIM(RIGHT(L11,2))) -> 2
A12: 9 | B12: Dự án mẫu (UDPM.NET) | C12: SOF205 | D12: UDPM | E12: Quiz 1-2 | F12: Quiz 3 | G12: Quiz 4 | H12: Quiz 5-6 | I12: Quiz 7 | J12: Quiz 8 | K12: Ôn + Thi | L12: Quiz 1-2 | M12: =IFERROR(MID(RIGHT(E12,2),FIND("-",RIGHT(E12,2),1)+1,2),TRIM(RIGHT(E12,2))) -> 2 | N12: =IFERROR(MID(RIGHT(F12,2),FIND("-",RIGHT(F12,2),1)+1,2),TRIM(RIGHT(F12,2))) -> 3 | O12: =IFERROR(MID(RIGHT(G12,2),FIND("-",RIGHT(G12,2),1)+1,2),TRIM(RIGHT(G12,2))) -> 4 | P12: =IFERROR(MID(RIGHT(H12,2),FIND("-",RIGHT(H12,2),1)+1,2),TRIM(RIGHT(H12,2))) -> 6 | Q12: =IFERROR(MID(RIGHT(I12,2),FIND("-",RIGHT(I12,2),1)+1,2),TRIM(RIGHT(I12,2))) -> 7 | R12: =IFERROR(MID(RIGHT(J12,2),FIND("-",RIGHT(J12,2),1)+1,2),TRIM(RIGHT(J12,2))) -> 8 | S12: =IFERROR(MID(RIGHT(K12,2),FIND("-",RIGHT(K12,2),1)+1,2),TRIM(RIGHT(K12,2))) -> hi | T12: =IFERROR(MID(RIGHT(L12,2),FIND("-",RIGHT(L12,2),1)+1,2),TRIM(RIGHT(L12,2))) -> 2
A13: 10 | B13: Dự án mẫu (UDPM.JAVA) | C13: SOF2041 | D13: UDPM | E13: Quiz 1-2 | F13: Quiz 3 | G13: Quiz 4 | H13: Quiz 5-6 | I13: Quiz 7 | J13: Quiz 8 | K13: Ôn + Thi | L13: Quiz 1-2 | M13: =IFERROR(MID(RIGHT(E13,2),FIND("-",RIGHT(E13,2),1)+1,2),TRIM(RIGHT(E13,2))) -> 2 | N13: =IFERROR(MID(RIGHT(F13,2),FIND("-",RIGHT(F13,2),1)+1,2),TRIM(RIGHT(F13,2))) -> 3 | O13: =IFERROR(MID(RIGHT(G13,2),FIND("-",RIGHT(G13,2),1)+1,2),TRIM(RIGHT(G13,2))) -> 4 | P13: =IFERROR(MID(RIGHT(H13,2),FIND("-",RIGHT(H13,2),1)+1,2),TRIM(RIGHT(H13,2))) -> 6 | Q13: =IFERROR(MID(RIGHT(I13,2),FIND("-",RIGHT(I13,2),1)+1,2),TRIM(RIGHT(I13,2))) -> 7 | R13: =IFERROR(MID(RIGHT(J13,2),FIND("-",RIGHT(J13,2),1)+1,2),TRIM(RIGHT(J13,2))) -> 8 | S13: =IFERROR(MID(RIGHT(K13,2),FIND("-",RIGHT(K13,2),1)+1,2),TRIM(RIGHT(K13,2))) -> hi | T13: =IFERROR(MID(RIGHT(L13,2),FIND("-",RIGHT(L13,2),1)+1,2),TRIM(RIGHT(L13,2))) -> 2
A14: 11 | B14: Kinh tế | C14: BUS1024 | D14: KT | E14: Quiz 1-3 | F14: Quiz 4-6 | G14: Quiz 7-8 | H14: Quiz 9-10 | I14: Quiz 11-12 | J14: Quiz 13-14 | K14: Ôn + Thi | L14: Quiz 1-3 | M14: =IFERROR(MID(RIGHT(E14,2),FIND("-",RIGHT(E14,2),1)+1,2),TRIM(RIGHT(E14,2))) -> 3 | N14: =IFERROR(MID(RIGHT(F14,2),FIND("-",RIGHT(F14,2),1)+1,2),TRIM(RIGHT(F14,2))) -> 6 | O14: =IFERROR(MID(RIGHT(G14,2),FIND("-",RIGHT(G14,2),1)+1,2),TRIM(RIGHT(G14,2))) -> 8 | P14: =IFERROR(MID(RIGHT(H14,2),FIND("-",RIGHT(H14,2),1)+1,2),TRIM(RIGHT(H14,2))) -> 10 | Q14: =IFERROR(MID(RIGHT(I14,2),FIND("-",RIGHT(I14,2),1)+1,2),TRIM(RIGHT(I14,2))) -> 12 | R14: =IFERROR(MID(RIGHT(J14,2),FIND("-",RIGHT(J14,2),1)+1,2),TRIM(RIGHT(J14,2))) -> 14 | S14: =IFERROR(MID(RIGHT(K14,2),FIND("-",RIGHT(K14,2),1)+1,2),TRIM(RIGHT(K14,2))) -> hi | T14: =IFERROR(MID(RIGHT(L14,2),FIND("-",RIGHT(L14,2),1)+1,2),TRIM(RIGHT(L14,2))) -> 3
